2019-11-04 14:13:34,301 - INFO - Бот стартанул
2019-11-04 14:13:34,302 - WARNING - Connection pool of Request object is smaller than optimal value (8)
2019-11-04 14:13:55,555 - WARNING - Connection pool is full, discarding connection: api.telegram.org
2019-11-04 14:13:55,557 - INFO - Запущена login_start 
2019-11-04 14:13:55,908 - INFO -  пользователь ввел Login
2019-11-04 14:14:03,180 - WARNING - Connection pool is full, discarding connection: api.telegram.org
2019-11-04 14:14:03,182 - INFO - Запущена login_check пользователь ввел V@sya
2019-11-04 14:14:03,495 - INFO - login_check Введенный логин содержит недопустимые символы ['@']
2019-11-04 14:14:13,252 - WARNING - Connection pool is full, discarding connection: api.telegram.org
2019-11-04 14:14:16,509 - INFO - Запущена login_check пользователь ввел asd
2019-11-04 14:14:26,579 - WARNING - Connection pool is full, discarding connection: api.telegram.org
2019-11-04 14:14:35,273 - INFO - Запущена login_check пользователь ввел gfjghfkfkfgkfgfkgfkghfkhfkhgfkgffkf
2019-11-04 14:14:45,344 - WARNING - Connection pool is full, discarding connection: api.telegram.org
2019-11-04 14:15:03,428 - INFO - Запущена login_check пользователь ввел Vasya
2019-11-04 14:15:03,786 - INFO - Пользователя с логином Vasya не существует. Зарегистрируйтесь или введите другой логин
2019-11-04 14:15:13,507 - WARNING - Connection pool is full, discarding connection: api.telegram.org
2019-11-04 14:27:54,059 - ERROR - Error while getting Updates: urllib3 HTTPError ('Connection aborted.', ConnectionResetError(10054, 'Удаленный хост принудительно разорвал существующее подключение', None, 10054, None))
2019-11-04 14:27:54,061 - ERROR - No error handlers are registered, logging exception.
Traceback (most recent call last):
  File "c:\projects\next_bot\env\lib\site-packages\telegram\vendor\ptb_urllib3\urllib3\connectionpool.py", line 617, in urlopen
    chunked=chunked)
  File "c:\projects\next_bot\env\lib\site-packages\telegram\vendor\ptb_urllib3\urllib3\connectionpool.py", line 402, in _make_request
    six.raise_from(e, None)
  File "<string>", line 2, in raise_from
  File "c:\projects\next_bot\env\lib\site-packages\telegram\vendor\ptb_urllib3\urllib3\connectionpool.py", line 398, in _make_request
    httplib_response = conn.getresponse()
  File "C:\Program Files\Python\Python373\lib\http\client.py", line 1321, in getresponse
    response.begin()
  File "C:\Program Files\Python\Python373\lib\http\client.py", line 296, in begin
    version, status, reason = self._read_status()
  File "C:\Program Files\Python\Python373\lib\http\client.py", line 257, in _read_status
    line = str(self.fp.readline(_MAXLINE + 1), "iso-8859-1")
  File "C:\Program Files\Python\Python373\lib\socket.py", line 589, in readinto
    return self._sock.recv_into(b)
  File "C:\Program Files\Python\Python373\lib\ssl.py", line 1052, in recv_into
    return self.read(nbytes, buffer)
  File "C:\Program Files\Python\Python373\lib\ssl.py", line 911, in read
    return self._sslobj.read(len, buffer)
ConnectionResetError: [WinError 10054] Удаленный хост принудительно разорвал существующее подключение

During handling of the above exception, another exception occurred:

Traceback (most recent call last):
  File "c:\projects\next_bot\env\lib\site-packages\telegram\utils\request.py", line 218, in _request_wrapper
    resp = self._con_pool.request(*args, **kwargs)
  File "c:\projects\next_bot\env\lib\site-packages\telegram\vendor\ptb_urllib3\urllib3\request.py", line 70, in request
    **urlopen_kw)
  File "c:\projects\next_bot\env\lib\site-packages\telegram\vendor\ptb_urllib3\urllib3\request.py", line 148, in request_encode_body
    return self.urlopen(method, url, **extra_kw)
  File "c:\projects\next_bot\env\lib\site-packages\telegram\vendor\ptb_urllib3\urllib3\poolmanager.py", line 244, in urlopen
    response = conn.urlopen(method, u.request_uri, **kw)
  File "c:\projects\next_bot\env\lib\site-packages\telegram\vendor\ptb_urllib3\urllib3\connectionpool.py", line 666, in urlopen
    _stacktrace=sys.exc_info()[2])
  File "c:\projects\next_bot\env\lib\site-packages\telegram\vendor\ptb_urllib3\urllib3\util\retry.py", line 347, in increment
    raise six.reraise(type(error), error, _stacktrace)
  File "c:\projects\next_bot\env\lib\site-packages\telegram\vendor\ptb_urllib3\urllib3\packages\six.py", line 685, in reraise
    raise value.with_traceback(tb)
  File "c:\projects\next_bot\env\lib\site-packages\telegram\vendor\ptb_urllib3\urllib3\connectionpool.py", line 617, in urlopen
    chunked=chunked)
  File "c:\projects\next_bot\env\lib\site-packages\telegram\vendor\ptb_urllib3\urllib3\connectionpool.py", line 402, in _make_request
    six.raise_from(e, None)
  File "<string>", line 2, in raise_from
  File "c:\projects\next_bot\env\lib\site-packages\telegram\vendor\ptb_urllib3\urllib3\connectionpool.py", line 398, in _make_request
    httplib_response = conn.getresponse()
  File "C:\Program Files\Python\Python373\lib\http\client.py", line 1321, in getresponse
    response.begin()
  File "C:\Program Files\Python\Python373\lib\http\client.py", line 296, in begin
    version, status, reason = self._read_status()
  File "C:\Program Files\Python\Python373\lib\http\client.py", line 257, in _read_status
    line = str(self.fp.readline(_MAXLINE + 1), "iso-8859-1")
  File "C:\Program Files\Python\Python373\lib\socket.py", line 589, in readinto
    return self._sock.recv_into(b)
  File "C:\Program Files\Python\Python373\lib\ssl.py", line 1052, in recv_into
    return self.read(nbytes, buffer)
  File "C:\Program Files\Python\Python373\lib\ssl.py", line 911, in read
    return self._sslobj.read(len, buffer)
telegram.vendor.ptb_urllib3.urllib3.exceptions.ProtocolError: ('Connection aborted.', ConnectionResetError(10054, 'Удаленный хост принудительно разорвал существующее подключение', None, 10054, None))

During handling of the above exception, another exception occurred:

Traceback (most recent call last):
  File "c:\projects\next_bot\env\lib\site-packages\telegram\ext\updater.py", line 332, in _network_loop_retry
    if not action_cb():
  File "c:\projects\next_bot\env\lib\site-packages\telegram\ext\updater.py", line 293, in polling_action_cb
    allowed_updates=allowed_updates)
  File "c:\projects\next_bot\env\lib\site-packages\telegram\bot.py", line 66, in decorator
    result = func(self, *args, **kwargs)
  File "c:\projects\next_bot\env\lib\site-packages\telegram\bot.py", line 1983, in get_updates
    result = self._request.post(url, data, timeout=float(read_latency) + float(timeout))
  File "c:\projects\next_bot\env\lib\site-packages\telegram\utils\request.py", line 327, in post
    **urlopen_kwargs)
  File "c:\projects\next_bot\env\lib\site-packages\telegram\utils\request.py", line 224, in _request_wrapper
    raise NetworkError('urllib3 HTTPError {0}'.format(error))
telegram.error.NetworkError: urllib3 HTTPError ('Connection aborted.', ConnectionResetError(10054, 'Удаленный хост принудительно разорвал существующее подключение', None, 10054, None))
2019-11-04 14:28:00,080 - WARNING - Retrying (Retry(total=2, connect=None, read=None, redirect=None)) after connection broken by 'ConnectTimeoutError(<telegram.vendor.ptb_urllib3.urllib3.connection.VerifiedHTTPSConnection object at 0x0000019CDE4A0278>, 'Connection to api.telegram.org timed out. (connect timeout=5.0)')': /bot822102958:AAHsgSxtLNp1FHMFXih30Rkpkx4DHFsvsFU/getUpdates
2019-11-04 14:28:05,081 - WARNING - Retrying (Retry(total=1, connect=None, read=None, redirect=None)) after connection broken by 'ConnectTimeoutError(<telegram.vendor.ptb_urllib3.urllib3.connection.VerifiedHTTPSConnection object at 0x0000019CDED4B668>, 'Connection to api.telegram.org timed out. (connect timeout=5.0)')': /bot822102958:AAHsgSxtLNp1FHMFXih30Rkpkx4DHFsvsFU/getUpdates
2019-11-04 14:28:05,437 - INFO - Received signal 2 (SIGINT), stopping...
