2019-11-02 11:39:52,197 - WARNING - Connection pool is full, discarding connection: api.telegram.org
2019-11-02 11:39:52,535 - INFO - Запущена  signup_start
2019-11-02 11:40:02,268 - WARNING - Connection pool is full, discarding connection: api.telegram.org
2019-11-02 11:40:14,338 - ERROR - No error handlers are registered, logging exception.
Traceback (most recent call last):
  File "c:\projects\next_bot\env\lib\site-packages\telegram\ext\dispatcher.py", line 368, in process_update
    check = handler.check_update(update)
  File "c:\projects\next_bot\env\lib\site-packages\telegram\ext\conversationhandler.py", line 300, in check_update
    check = entry_point.check_update(update)
AttributeError: 'NoneType' object has no attribute 'check_update'
2019-11-02 11:40:44,011 - ERROR - No error handlers are registered, logging exception.
Traceback (most recent call last):
  File "c:\projects\next_bot\env\lib\site-packages\telegram\ext\dispatcher.py", line 368, in process_update
    check = handler.check_update(update)
  File "c:\projects\next_bot\env\lib\site-packages\telegram\ext\conversationhandler.py", line 300, in check_update
    check = entry_point.check_update(update)
AttributeError: 'NoneType' object has no attribute 'check_update'
2019-11-02 11:40:56,711 - INFO - Запущена  signup_get_name_and_surname
2019-11-02 11:40:57,070 - INFO -  vvod 1 Запущена  signup_get_name_and_surname  юзер ввел не 2 строки
2019-11-02 11:41:06,781 - WARNING - Connection pool is full, discarding connection: api.telegram.org
2019-11-02 11:48:46,041 - INFO - Бот стартанул
2019-11-02 11:48:46,041 - WARNING - Connection pool of Request object is smaller than optimal value (8)
2019-11-02 11:48:57,043 - WARNING - Connection pool is full, discarding connection: api.telegram.org
2019-11-02 11:48:57,353 - INFO - Запущена  signup_start
2019-11-02 11:48:59,811 - WARNING - Connection pool is full, discarding connection: api.telegram.org
2019-11-02 11:48:59,814 - ERROR - No error handlers are registered, logging exception.
Traceback (most recent call last):
  File "c:\projects\next_bot\env\lib\site-packages\telegram\ext\dispatcher.py", line 368, in process_update
    check = handler.check_update(update)
  File "c:\projects\next_bot\env\lib\site-packages\telegram\ext\conversationhandler.py", line 300, in check_update
    check = entry_point.check_update(update)
AttributeError: 'NoneType' object has no attribute 'check_update'
2019-11-02 11:50:44,461 - INFO - Бот стартанул
2019-11-02 11:50:44,461 - WARNING - Connection pool of Request object is smaller than optimal value (8)
2019-11-02 11:50:52,963 - WARNING - Connection pool is full, discarding connection: api.telegram.org
2019-11-02 11:50:53,374 - INFO - Запущена  signup_start
2019-11-02 11:50:58,942 - WARNING - Connection pool is full, discarding connection: api.telegram.org
2019-11-02 11:50:58,944 - ERROR - No error handlers are registered, logging exception.
Traceback (most recent call last):
  File "c:\projects\next_bot\env\lib\site-packages\telegram\ext\dispatcher.py", line 368, in process_update
    check = handler.check_update(update)
  File "c:\projects\next_bot\env\lib\site-packages\telegram\ext\conversationhandler.py", line 300, in check_update
    check = entry_point.check_update(update)
AttributeError: 'NoneType' object has no attribute 'check_update'
2019-11-02 11:52:55,843 - INFO - Бот стартанул
2019-11-02 11:52:55,844 - WARNING - Connection pool of Request object is smaller than optimal value (8)
2019-11-02 11:53:02,637 - WARNING - Connection pool is full, discarding connection: api.telegram.org
2019-11-02 11:53:03,002 - INFO - Запущена  signup_start
2019-11-02 11:53:05,063 - WARNING - Connection pool is full, discarding connection: api.telegram.org
2019-11-02 11:53:05,065 - ERROR - No error handlers are registered, logging exception.
Traceback (most recent call last):
  File "c:\projects\next_bot\env\lib\site-packages\telegram\ext\dispatcher.py", line 368, in process_update
    check = handler.check_update(update)
  File "c:\projects\next_bot\env\lib\site-packages\telegram\ext\conversationhandler.py", line 300, in check_update
    check = entry_point.check_update(update)
AttributeError: 'NoneType' object has no attribute 'check_update'
2019-11-02 11:53:19,424 - WARNING - Connection pool is full, discarding connection: api.telegram.org
2019-11-02 11:53:19,745 - INFO - Запущена  signup_start
2019-11-02 11:53:21,355 - WARNING - Connection pool is full, discarding connection: api.telegram.org
2019-11-02 11:53:21,357 - ERROR - No error handlers are registered, logging exception.
Traceback (most recent call last):
  File "c:\projects\next_bot\env\lib\site-packages\telegram\ext\dispatcher.py", line 368, in process_update
    check = handler.check_update(update)
  File "c:\projects\next_bot\env\lib\site-packages\telegram\ext\conversationhandler.py", line 300, in check_update
    check = entry_point.check_update(update)
AttributeError: 'NoneType' object has no attribute 'check_update'
2019-11-02 11:58:21,233 - INFO - Бот стартанул
2019-11-02 11:58:21,233 - WARNING - Connection pool of Request object is smaller than optimal value (8)
2019-11-02 11:58:25,392 - WARNING - Connection pool is full, discarding connection: api.telegram.org
2019-11-02 11:58:25,735 - INFO - Запущена  signup_start
2019-11-02 11:58:28,154 - WARNING - Connection pool is full, discarding connection: api.telegram.org
2019-11-02 11:58:28,156 - INFO - Запущена  signup_get_name_and_surname
2019-11-02 11:58:28,470 - INFO -  vvod 1 Запущена  signup_get_name_and_surname  юзер ввел не 2 строки
2019-11-02 11:58:38,236 - WARNING - Connection pool is full, discarding connection: api.telegram.org
2019-11-02 12:00:43,393 - INFO - Запущена  signup_get_name_and_surname
2019-11-02 12:00:43,393 - INFO - Запущена  signup_get_name_and_surname  юзер ввел  2 строки. Имя и фамилия сохранены
2019-11-02 12:00:53,473 - WARNING - Connection pool is full, discarding connection: api.telegram.org
2019-11-02 12:19:02,413 - ERROR - Error while getting Updates: urllib3 HTTPError ('Connection aborted.', ConnectionResetError(10054, 'Удаленный хост принудительно разорвал существующее подключение', None, 10054, None))
2019-11-02 12:19:02,413 - ERROR - No error handlers are registered, logging exception.
Traceback (most recent call last):
  File "c:\projects\next_bot\env\lib\site-packages\telegram\vendor\ptb_urllib3\urllib3\connectionpool.py", line 617, in urlopen
    chunked=chunked)
  File "c:\projects\next_bot\env\lib\site-packages\telegram\vendor\ptb_urllib3\urllib3\connectionpool.py", line 402, in _make_request
    six.raise_from(e, None)
  File "<string>", line 2, in raise_from
  File "c:\projects\next_bot\env\lib\site-packages\telegram\vendor\ptb_urllib3\urllib3\connectionpool.py", line 398, in _make_request
    httplib_response = conn.getresponse()
  File "C:\Program Files\Python\Python373\lib\http\client.py", line 1321, in getresponse
    response.begin()
  File "C:\Program Files\Python\Python373\lib\http\client.py", line 296, in begin
    version, status, reason = self._read_status()
  File "C:\Program Files\Python\Python373\lib\http\client.py", line 257, in _read_status
    line = str(self.fp.readline(_MAXLINE + 1), "iso-8859-1")
  File "C:\Program Files\Python\Python373\lib\socket.py", line 589, in readinto
    return self._sock.recv_into(b)
  File "C:\Program Files\Python\Python373\lib\ssl.py", line 1052, in recv_into
    return self.read(nbytes, buffer)
  File "C:\Program Files\Python\Python373\lib\ssl.py", line 911, in read
    return self._sslobj.read(len, buffer)
ConnectionResetError: [WinError 10054] Удаленный хост принудительно разорвал существующее подключение

During handling of the above exception, another exception occurred:

Traceback (most recent call last):
  File "c:\projects\next_bot\env\lib\site-packages\telegram\utils\request.py", line 218, in _request_wrapper
    resp = self._con_pool.request(*args, **kwargs)
  File "c:\projects\next_bot\env\lib\site-packages\telegram\vendor\ptb_urllib3\urllib3\request.py", line 70, in request
    **urlopen_kw)
  File "c:\projects\next_bot\env\lib\site-packages\telegram\vendor\ptb_urllib3\urllib3\request.py", line 148, in request_encode_body
    return self.urlopen(method, url, **extra_kw)
  File "c:\projects\next_bot\env\lib\site-packages\telegram\vendor\ptb_urllib3\urllib3\poolmanager.py", line 244, in urlopen
    response = conn.urlopen(method, u.request_uri, **kw)
  File "c:\projects\next_bot\env\lib\site-packages\telegram\vendor\ptb_urllib3\urllib3\connectionpool.py", line 666, in urlopen
    _stacktrace=sys.exc_info()[2])
  File "c:\projects\next_bot\env\lib\site-packages\telegram\vendor\ptb_urllib3\urllib3\util\retry.py", line 347, in increment
    raise six.reraise(type(error), error, _stacktrace)
  File "c:\projects\next_bot\env\lib\site-packages\telegram\vendor\ptb_urllib3\urllib3\packages\six.py", line 685, in reraise
    raise value.with_traceback(tb)
  File "c:\projects\next_bot\env\lib\site-packages\telegram\vendor\ptb_urllib3\urllib3\connectionpool.py", line 617, in urlopen
    chunked=chunked)
  File "c:\projects\next_bot\env\lib\site-packages\telegram\vendor\ptb_urllib3\urllib3\connectionpool.py", line 402, in _make_request
    six.raise_from(e, None)
  File "<string>", line 2, in raise_from
  File "c:\projects\next_bot\env\lib\site-packages\telegram\vendor\ptb_urllib3\urllib3\connectionpool.py", line 398, in _make_request
    httplib_response = conn.getresponse()
  File "C:\Program Files\Python\Python373\lib\http\client.py", line 1321, in getresponse
    response.begin()
  File "C:\Program Files\Python\Python373\lib\http\client.py", line 296, in begin
    version, status, reason = self._read_status()
  File "C:\Program Files\Python\Python373\lib\http\client.py", line 257, in _read_status
    line = str(self.fp.readline(_MAXLINE + 1), "iso-8859-1")
  File "C:\Program Files\Python\Python373\lib\socket.py", line 589, in readinto
    return self._sock.recv_into(b)
  File "C:\Program Files\Python\Python373\lib\ssl.py", line 1052, in recv_into
    return self.read(nbytes, buffer)
  File "C:\Program Files\Python\Python373\lib\ssl.py", line 911, in read
    return self._sslobj.read(len, buffer)
telegram.vendor.ptb_urllib3.urllib3.exceptions.ProtocolError: ('Connection aborted.', ConnectionResetError(10054, 'Удаленный хост принудительно разорвал существующее подключение', None, 10054, None))

During handling of the above exception, another exception occurred:

Traceback (most recent call last):
  File "c:\projects\next_bot\env\lib\site-packages\telegram\ext\updater.py", line 332, in _network_loop_retry
    if not action_cb():
  File "c:\projects\next_bot\env\lib\site-packages\telegram\ext\updater.py", line 293, in polling_action_cb
    allowed_updates=allowed_updates)
  File "c:\projects\next_bot\env\lib\site-packages\telegram\bot.py", line 66, in decorator
    result = func(self, *args, **kwargs)
  File "c:\projects\next_bot\env\lib\site-packages\telegram\bot.py", line 1983, in get_updates
    result = self._request.post(url, data, timeout=float(read_latency) + float(timeout))
  File "c:\projects\next_bot\env\lib\site-packages\telegram\utils\request.py", line 327, in post
    **urlopen_kwargs)
  File "c:\projects\next_bot\env\lib\site-packages\telegram\utils\request.py", line 224, in _request_wrapper
    raise NetworkError('urllib3 HTTPError {0}'.format(error))
telegram.error.NetworkError: urllib3 HTTPError ('Connection aborted.', ConnectionResetError(10054, 'Удаленный хост принудительно разорвал существующее подключение', None, 10054, None))
2019-11-02 12:19:08,433 - WARNING - Retrying (Retry(total=2, connect=None, read=None, redirect=None)) after connection broken by 'ConnectTimeoutError(<telegram.vendor.ptb_urllib3.urllib3.connection.VerifiedHTTPSConnection object at 0x0000012DE7331BA8>, 'Connection to api.telegram.org timed out. (connect timeout=5.0)')': /bot822102958:AAHsgSxtLNp1FHMFXih30Rkpkx4DHFsvsFU/getUpdates
2019-11-02 12:19:13,434 - WARNING - Retrying (Retry(total=1, connect=None, read=None, redirect=None)) after connection broken by 'ConnectTimeoutError(<telegram.vendor.ptb_urllib3.urllib3.connection.VerifiedHTTPSConnection object at 0x0000012DE735FFD0>, 'Connection to api.telegram.org timed out. (connect timeout=5.0)')': /bot822102958:AAHsgSxtLNp1FHMFXih30Rkpkx4DHFsvsFU/getUpdates
2019-11-02 12:19:18,448 - WARNING - Retrying (Retry(total=0, connect=None, read=None, redirect=None)) after connection broken by 'ConnectTimeoutError(<telegram.vendor.ptb_urllib3.urllib3.connection.VerifiedHTTPSConnection object at 0x0000012DE7C480F0>, 'Connection to api.telegram.org timed out. (connect timeout=5.0)')': /bot822102958:AAHsgSxtLNp1FHMFXih30Rkpkx4DHFsvsFU/getUpdates
2019-11-02 12:19:23,449 - ERROR - Error while getting Updates: urllib3 HTTPError HTTPSConnectionPool(host='api.telegram.org', port=443): Max retries exceeded with url: /bot822102958:AAHsgSxtLNp1FHMFXih30Rkpkx4DHFsvsFU/getUpdates (Caused by ConnectTimeoutError(<telegram.vendor.ptb_urllib3.urllib3.connection.VerifiedHTTPSConnection object at 0x0000012DE7C481D0>, 'Connection to api.telegram.org timed out. (connect timeout=5.0)'))
2019-11-02 12:19:23,449 - ERROR - No error handlers are registered, logging exception.
Traceback (most recent call last):
  File "c:\projects\next_bot\env\lib\site-packages\telegram\vendor\ptb_urllib3\urllib3\connection.py", line 141, in _new_conn
    (self.host, self.port), self.timeout, **extra_kw)
  File "c:\projects\next_bot\env\lib\site-packages\telegram\vendor\ptb_urllib3\urllib3\util\connection.py", line 83, in create_connection
    raise err
  File "c:\projects\next_bot\env\lib\site-packages\telegram\vendor\ptb_urllib3\urllib3\util\connection.py", line 73, in create_connection
    sock.connect(sa)
socket.timeout: timed out

During handling of the above exception, another exception occurred:

Traceback (most recent call last):
  File "c:\projects\next_bot\env\lib\site-packages\telegram\vendor\ptb_urllib3\urllib3\connectionpool.py", line 617, in urlopen
    chunked=chunked)
  File "c:\projects\next_bot\env\lib\site-packages\telegram\vendor\ptb_urllib3\urllib3\connectionpool.py", line 360, in _make_request
    self._validate_conn(conn)
  File "c:\projects\next_bot\env\lib\site-packages\telegram\vendor\ptb_urllib3\urllib3\connectionpool.py", line 857, in _validate_conn
    super(HTTPSConnectionPool, self)._validate_conn(conn)
  File "c:\projects\next_bot\env\lib\site-packages\telegram\vendor\ptb_urllib3\urllib3\connectionpool.py", line 289, in _validate_conn
    conn.connect()
  File "c:\projects\next_bot\env\lib\site-packages\telegram\vendor\ptb_urllib3\urllib3\connection.py", line 284, in connect
    conn = self._new_conn()
  File "c:\projects\next_bot\env\lib\site-packages\telegram\vendor\ptb_urllib3\urllib3\connection.py", line 146, in _new_conn
    (self.host, self.timeout))
telegram.vendor.ptb_urllib3.urllib3.exceptions.ConnectTimeoutError: (<telegram.vendor.ptb_urllib3.urllib3.connection.VerifiedHTTPSConnection object at 0x0000012DE7C481D0>, 'Connection to api.telegram.org timed out. (connect timeout=5.0)')

During handling of the above exception, another exception occurred:

Traceback (most recent call last):
  File "c:\projects\next_bot\env\lib\site-packages\telegram\utils\request.py", line 218, in _request_wrapper
    resp = self._con_pool.request(*args, **kwargs)
  File "c:\projects\next_bot\env\lib\site-packages\telegram\vendor\ptb_urllib3\urllib3\request.py", line 70, in request
    **urlopen_kw)
  File "c:\projects\next_bot\env\lib\site-packages\telegram\vendor\ptb_urllib3\urllib3\request.py", line 148, in request_encode_body
    return self.urlopen(method, url, **extra_kw)
  File "c:\projects\next_bot\env\lib\site-packages\telegram\vendor\ptb_urllib3\urllib3\poolmanager.py", line 244, in urlopen
    response = conn.urlopen(method, u.request_uri, **kw)
  File "c:\projects\next_bot\env\lib\site-packages\telegram\vendor\ptb_urllib3\urllib3\connectionpool.py", line 695, in urlopen
    **response_kw)
  File "c:\projects\next_bot\env\lib\site-packages\telegram\vendor\ptb_urllib3\urllib3\connectionpool.py", line 695, in urlopen
    **response_kw)
  File "c:\projects\next_bot\env\lib\site-packages\telegram\vendor\ptb_urllib3\urllib3\connectionpool.py", line 695, in urlopen
    **response_kw)
  File "c:\projects\next_bot\env\lib\site-packages\telegram\vendor\ptb_urllib3\urllib3\connectionpool.py", line 666, in urlopen
    _stacktrace=sys.exc_info()[2])
  File "c:\projects\next_bot\env\lib\site-packages\telegram\vendor\ptb_urllib3\urllib3\util\retry.py", line 376, in increment
    raise MaxRetryError(_pool, url, error or ResponseError(cause))
telegram.vendor.ptb_urllib3.urllib3.exceptions.MaxRetryError: HTTPSConnectionPool(host='api.telegram.org', port=443): Max retries exceeded with url: /bot822102958:AAHsgSxtLNp1FHMFXih30Rkpkx4DHFsvsFU/getUpdates (Caused by ConnectTimeoutError(<telegram.vendor.ptb_urllib3.urllib3.connection.VerifiedHTTPSConnection object at 0x0000012DE7C481D0>, 'Connection to api.telegram.org timed out. (connect timeout=5.0)'))

During handling of the above exception, another exception occurred:

Traceback (most recent call last):
  File "c:\projects\next_bot\env\lib\site-packages\telegram\ext\updater.py", line 332, in _network_loop_retry
    if not action_cb():
  File "c:\projects\next_bot\env\lib\site-packages\telegram\ext\updater.py", line 293, in polling_action_cb
    allowed_updates=allowed_updates)
  File "c:\projects\next_bot\env\lib\site-packages\telegram\bot.py", line 66, in decorator
    result = func(self, *args, **kwargs)
  File "c:\projects\next_bot\env\lib\site-packages\telegram\bot.py", line 1983, in get_updates
    result = self._request.post(url, data, timeout=float(read_latency) + float(timeout))
  File "c:\projects\next_bot\env\lib\site-packages\telegram\utils\request.py", line 327, in post
    **urlopen_kwargs)
  File "c:\projects\next_bot\env\lib\site-packages\telegram\utils\request.py", line 224, in _request_wrapper
    raise NetworkError('urllib3 HTTPError {0}'.format(error))
telegram.error.NetworkError: urllib3 HTTPError HTTPSConnectionPool(host='api.telegram.org', port=443): Max retries exceeded with url: /bot822102958:AAHsgSxtLNp1FHMFXih30Rkpkx4DHFsvsFU/getUpdates (Caused by ConnectTimeoutError(<telegram.vendor.ptb_urllib3.urllib3.connection.VerifiedHTTPSConnection object at 0x0000012DE7C481D0>, 'Connection to api.telegram.org timed out. (connect timeout=5.0)'))
2019-11-02 12:19:29,951 - WARNING - Retrying (Retry(total=2, connect=None, read=None, redirect=None)) after connection broken by 'ConnectTimeoutError(<telegram.vendor.ptb_urllib3.urllib3.connection.VerifiedHTTPSConnection object at 0x0000012DE7C48358>, 'Connection to api.telegram.org timed out. (connect timeout=5.0)')': /bot822102958:AAHsgSxtLNp1FHMFXih30Rkpkx4DHFsvsFU/getUpdates
2019-11-02 12:19:34,953 - WARNING - Retrying (Retry(total=1, connect=None, read=None, redirect=None)) after connection broken by 'ConnectTimeoutError(<telegram.vendor.ptb_urllib3.urllib3.connection.VerifiedHTTPSConnection object at 0x0000012DE7C48588>, 'Connection to api.telegram.org timed out. (connect timeout=5.0)')': /bot822102958:AAHsgSxtLNp1FHMFXih30Rkpkx4DHFsvsFU/getUpdates
2019-11-02 12:19:39,955 - WARNING - Retrying (Retry(total=0, connect=None, read=None, redirect=None)) after connection broken by 'ConnectTimeoutError(<telegram.vendor.ptb_urllib3.urllib3.connection.VerifiedHTTPSConnection object at 0x0000012DE7C48668>, 'Connection to api.telegram.org timed out. (connect timeout=5.0)')': /bot822102958:AAHsgSxtLNp1FHMFXih30Rkpkx4DHFsvsFU/getUpdates
2019-11-02 12:19:44,956 - ERROR - Error while getting Updates: urllib3 HTTPError HTTPSConnectionPool(host='api.telegram.org', port=443): Max retries exceeded with url: /bot822102958:AAHsgSxtLNp1FHMFXih30Rkpkx4DHFsvsFU/getUpdates (Caused by ConnectTimeoutError(<telegram.vendor.ptb_urllib3.urllib3.connection.VerifiedHTTPSConnection object at 0x0000012DE7C48748>, 'Connection to api.telegram.org timed out. (connect timeout=5.0)'))
2019-11-02 12:19:44,956 - ERROR - No error handlers are registered, logging exception.
Traceback (most recent call last):
  File "c:\projects\next_bot\env\lib\site-packages\telegram\vendor\ptb_urllib3\urllib3\connection.py", line 141, in _new_conn
    (self.host, self.port), self.timeout, **extra_kw)
  File "c:\projects\next_bot\env\lib\site-packages\telegram\vendor\ptb_urllib3\urllib3\util\connection.py", line 83, in create_connection
    raise err
  File "c:\projects\next_bot\env\lib\site-packages\telegram\vendor\ptb_urllib3\urllib3\util\connection.py", line 73, in create_connection
    sock.connect(sa)
socket.timeout: timed out

During handling of the above exception, another exception occurred:

Traceback (most recent call last):
  File "c:\projects\next_bot\env\lib\site-packages\telegram\vendor\ptb_urllib3\urllib3\connectionpool.py", line 617, in urlopen
    chunked=chunked)
  File "c:\projects\next_bot\env\lib\site-packages\telegram\vendor\ptb_urllib3\urllib3\connectionpool.py", line 360, in _make_request
    self._validate_conn(conn)
  File "c:\projects\next_bot\env\lib\site-packages\telegram\vendor\ptb_urllib3\urllib3\connectionpool.py", line 857, in _validate_conn
    super(HTTPSConnectionPool, self)._validate_conn(conn)
  File "c:\projects\next_bot\env\lib\site-packages\telegram\vendor\ptb_urllib3\urllib3\connectionpool.py", line 289, in _validate_conn
    conn.connect()
  File "c:\projects\next_bot\env\lib\site-packages\telegram\vendor\ptb_urllib3\urllib3\connection.py", line 284, in connect
    conn = self._new_conn()
  File "c:\projects\next_bot\env\lib\site-packages\telegram\vendor\ptb_urllib3\urllib3\connection.py", line 146, in _new_conn
    (self.host, self.timeout))
telegram.vendor.ptb_urllib3.urllib3.exceptions.ConnectTimeoutError: (<telegram.vendor.ptb_urllib3.urllib3.connection.VerifiedHTTPSConnection object at 0x0000012DE7C48748>, 'Connection to api.telegram.org timed out. (connect timeout=5.0)')

During handling of the above exception, another exception occurred:

Traceback (most recent call last):
  File "c:\projects\next_bot\env\lib\site-packages\telegram\utils\request.py", line 218, in _request_wrapper
    resp = self._con_pool.request(*args, **kwargs)
  File "c:\projects\next_bot\env\lib\site-packages\telegram\vendor\ptb_urllib3\urllib3\request.py", line 70, in request
    **urlopen_kw)
  File "c:\projects\next_bot\env\lib\site-packages\telegram\vendor\ptb_urllib3\urllib3\request.py", line 148, in request_encode_body
    return self.urlopen(method, url, **extra_kw)
  File "c:\projects\next_bot\env\lib\site-packages\telegram\vendor\ptb_urllib3\urllib3\poolmanager.py", line 244, in urlopen
    response = conn.urlopen(method, u.request_uri, **kw)
  File "c:\projects\next_bot\env\lib\site-packages\telegram\vendor\ptb_urllib3\urllib3\connectionpool.py", line 695, in urlopen
    **response_kw)
  File "c:\projects\next_bot\env\lib\site-packages\telegram\vendor\ptb_urllib3\urllib3\connectionpool.py", line 695, in urlopen
    **response_kw)
  File "c:\projects\next_bot\env\lib\site-packages\telegram\vendor\ptb_urllib3\urllib3\connectionpool.py", line 695, in urlopen
    **response_kw)
  File "c:\projects\next_bot\env\lib\site-packages\telegram\vendor\ptb_urllib3\urllib3\connectionpool.py", line 666, in urlopen
    _stacktrace=sys.exc_info()[2])
  File "c:\projects\next_bot\env\lib\site-packages\telegram\vendor\ptb_urllib3\urllib3\util\retry.py", line 376, in increment
    raise MaxRetryError(_pool, url, error or ResponseError(cause))
telegram.vendor.ptb_urllib3.urllib3.exceptions.MaxRetryError: HTTPSConnectionPool(host='api.telegram.org', port=443): Max retries exceeded with url: /bot822102958:AAHsgSxtLNp1FHMFXih30Rkpkx4DHFsvsFU/getUpdates (Caused by ConnectTimeoutError(<telegram.vendor.ptb_urllib3.urllib3.connection.VerifiedHTTPSConnection object at 0x0000012DE7C48748>, 'Connection to api.telegram.org timed out. (connect timeout=5.0)'))

During handling of the above exception, another exception occurred:

Traceback (most recent call last):
  File "c:\projects\next_bot\env\lib\site-packages\telegram\ext\updater.py", line 332, in _network_loop_retry
    if not action_cb():
  File "c:\projects\next_bot\env\lib\site-packages\telegram\ext\updater.py", line 293, in polling_action_cb
    allowed_updates=allowed_updates)
  File "c:\projects\next_bot\env\lib\site-packages\telegram\bot.py", line 66, in decorator
    result = func(self, *args, **kwargs)
  File "c:\projects\next_bot\env\lib\site-packages\telegram\bot.py", line 1983, in get_updates
    result = self._request.post(url, data, timeout=float(read_latency) + float(timeout))
  File "c:\projects\next_bot\env\lib\site-packages\telegram\utils\request.py", line 327, in post
    **urlopen_kwargs)
  File "c:\projects\next_bot\env\lib\site-packages\telegram\utils\request.py", line 224, in _request_wrapper
    raise NetworkError('urllib3 HTTPError {0}'.format(error))
telegram.error.NetworkError: urllib3 HTTPError HTTPSConnectionPool(host='api.telegram.org', port=443): Max retries exceeded with url: /bot822102958:AAHsgSxtLNp1FHMFXih30Rkpkx4DHFsvsFU/getUpdates (Caused by ConnectTimeoutError(<telegram.vendor.ptb_urllib3.urllib3.connection.VerifiedHTTPSConnection object at 0x0000012DE7C48748>, 'Connection to api.telegram.org timed out. (connect timeout=5.0)'))
2019-11-02 12:19:52,209 - WARNING - Retrying (Retry(total=2, connect=None, read=None, redirect=None)) after connection broken by 'ConnectTimeoutError(<telegram.vendor.ptb_urllib3.urllib3.connection.VerifiedHTTPSConnection object at 0x0000012DE7C482E8>, 'Connection to api.telegram.org timed out. (connect timeout=5.0)')': /bot822102958:AAHsgSxtLNp1FHMFXih30Rkpkx4DHFsvsFU/getUpdates
2019-11-02 12:19:57,210 - WARNING - Retrying (Retry(total=1, connect=None, read=None, redirect=None)) after connection broken by 'ConnectTimeoutError(<telegram.vendor.ptb_urllib3.urllib3.connection.VerifiedHTTPSConnection object at 0x0000012DE7C489E8>, 'Connection to api.telegram.org timed out. (connect timeout=5.0)')': /bot822102958:AAHsgSxtLNp1FHMFXih30Rkpkx4DHFsvsFU/getUpdates
2019-11-02 12:20:02,213 - WARNING - Retrying (Retry(total=0, connect=None, read=None, redirect=None)) after connection broken by 'ConnectTimeoutError(<telegram.vendor.ptb_urllib3.urllib3.connection.VerifiedHTTPSConnection object at 0x0000012DE7C48AC8>, 'Connection to api.telegram.org timed out. (connect timeout=5.0)')': /bot822102958:AAHsgSxtLNp1FHMFXih30Rkpkx4DHFsvsFU/getUpdates
2019-11-02 12:20:07,214 - ERROR - Error while getting Updates: urllib3 HTTPError HTTPSConnectionPool(host='api.telegram.org', port=443): Max retries exceeded with url: /bot822102958:AAHsgSxtLNp1FHMFXih30Rkpkx4DHFsvsFU/getUpdates (Caused by ConnectTimeoutError(<telegram.vendor.ptb_urllib3.urllib3.connection.VerifiedHTTPSConnection object at 0x0000012DE735FFD0>, 'Connection to api.telegram.org timed out. (connect timeout=5.0)'))
2019-11-02 12:20:07,214 - ERROR - No error handlers are registered, logging exception.
Traceback (most recent call last):
  File "c:\projects\next_bot\env\lib\site-packages\telegram\vendor\ptb_urllib3\urllib3\connection.py", line 141, in _new_conn
    (self.host, self.port), self.timeout, **extra_kw)
  File "c:\projects\next_bot\env\lib\site-packages\telegram\vendor\ptb_urllib3\urllib3\util\connection.py", line 83, in create_connection
    raise err
  File "c:\projects\next_bot\env\lib\site-packages\telegram\vendor\ptb_urllib3\urllib3\util\connection.py", line 73, in create_connection
    sock.connect(sa)
socket.timeout: timed out

During handling of the above exception, another exception occurred:

Traceback (most recent call last):
  File "c:\projects\next_bot\env\lib\site-packages\telegram\vendor\ptb_urllib3\urllib3\connectionpool.py", line 617, in urlopen
    chunked=chunked)
  File "c:\projects\next_bot\env\lib\site-packages\telegram\vendor\ptb_urllib3\urllib3\connectionpool.py", line 360, in _make_request
    self._validate_conn(conn)
  File "c:\projects\next_bot\env\lib\site-packages\telegram\vendor\ptb_urllib3\urllib3\connectionpool.py", line 857, in _validate_conn
    super(HTTPSConnectionPool, self)._validate_conn(conn)
  File "c:\projects\next_bot\env\lib\site-packages\telegram\vendor\ptb_urllib3\urllib3\connectionpool.py", line 289, in _validate_conn
    conn.connect()
  File "c:\projects\next_bot\env\lib\site-packages\telegram\vendor\ptb_urllib3\urllib3\connection.py", line 284, in connect
    conn = self._new_conn()
  File "c:\projects\next_bot\env\lib\site-packages\telegram\vendor\ptb_urllib3\urllib3\connection.py", line 146, in _new_conn
    (self.host, self.timeout))
telegram.vendor.ptb_urllib3.urllib3.exceptions.ConnectTimeoutError: (<telegram.vendor.ptb_urllib3.urllib3.connection.VerifiedHTTPSConnection object at 0x0000012DE735FFD0>, 'Connection to api.telegram.org timed out. (connect timeout=5.0)')

During handling of the above exception, another exception occurred:

Traceback (most recent call last):
  File "c:\projects\next_bot\env\lib\site-packages\telegram\utils\request.py", line 218, in _request_wrapper
    resp = self._con_pool.request(*args, **kwargs)
  File "c:\projects\next_bot\env\lib\site-packages\telegram\vendor\ptb_urllib3\urllib3\request.py", line 70, in request
    **urlopen_kw)
  File "c:\projects\next_bot\env\lib\site-packages\telegram\vendor\ptb_urllib3\urllib3\request.py", line 148, in request_encode_body
    return self.urlopen(method, url, **extra_kw)
  File "c:\projects\next_bot\env\lib\site-packages\telegram\vendor\ptb_urllib3\urllib3\poolmanager.py", line 244, in urlopen
    response = conn.urlopen(method, u.request_uri, **kw)
  File "c:\projects\next_bot\env\lib\site-packages\telegram\vendor\ptb_urllib3\urllib3\connectionpool.py", line 695, in urlopen
    **response_kw)
  File "c:\projects\next_bot\env\lib\site-packages\telegram\vendor\ptb_urllib3\urllib3\connectionpool.py", line 695, in urlopen
    **response_kw)
  File "c:\projects\next_bot\env\lib\site-packages\telegram\vendor\ptb_urllib3\urllib3\connectionpool.py", line 695, in urlopen
    **response_kw)
  File "c:\projects\next_bot\env\lib\site-packages\telegram\vendor\ptb_urllib3\urllib3\connectionpool.py", line 666, in urlopen
    _stacktrace=sys.exc_info()[2])
  File "c:\projects\next_bot\env\lib\site-packages\telegram\vendor\ptb_urllib3\urllib3\util\retry.py", line 376, in increment
    raise MaxRetryError(_pool, url, error or ResponseError(cause))
telegram.vendor.ptb_urllib3.urllib3.exceptions.MaxRetryError: HTTPSConnectionPool(host='api.telegram.org', port=443): Max retries exceeded with url: /bot822102958:AAHsgSxtLNp1FHMFXih30Rkpkx4DHFsvsFU/getUpdates (Caused by ConnectTimeoutError(<telegram.vendor.ptb_urllib3.urllib3.connection.VerifiedHTTPSConnection object at 0x0000012DE735FFD0>, 'Connection to api.telegram.org timed out. (connect timeout=5.0)'))

During handling of the above exception, another exception occurred:

Traceback (most recent call last):
  File "c:\projects\next_bot\env\lib\site-packages\telegram\ext\updater.py", line 332, in _network_loop_retry
    if not action_cb():
  File "c:\projects\next_bot\env\lib\site-packages\telegram\ext\updater.py", line 293, in polling_action_cb
    allowed_updates=allowed_updates)
  File "c:\projects\next_bot\env\lib\site-packages\telegram\bot.py", line 66, in decorator
    result = func(self, *args, **kwargs)
  File "c:\projects\next_bot\env\lib\site-packages\telegram\bot.py", line 1983, in get_updates
    result = self._request.post(url, data, timeout=float(read_latency) + float(timeout))
  File "c:\projects\next_bot\env\lib\site-packages\telegram\utils\request.py", line 327, in post
    **urlopen_kwargs)
  File "c:\projects\next_bot\env\lib\site-packages\telegram\utils\request.py", line 224, in _request_wrapper
    raise NetworkError('urllib3 HTTPError {0}'.format(error))
telegram.error.NetworkError: urllib3 HTTPError HTTPSConnectionPool(host='api.telegram.org', port=443): Max retries exceeded with url: /bot822102958:AAHsgSxtLNp1FHMFXih30Rkpkx4DHFsvsFU/getUpdates (Caused by ConnectTimeoutError(<telegram.vendor.ptb_urllib3.urllib3.connection.VerifiedHTTPSConnection object at 0x0000012DE735FFD0>, 'Connection to api.telegram.org timed out. (connect timeout=5.0)'))
2019-11-02 12:20:15,592 - WARNING - Retrying (Retry(total=2, connect=None, read=None, redirect=None)) after connection broken by 'ConnectTimeoutError(<telegram.vendor.ptb_urllib3.urllib3.connection.VerifiedHTTPSConnection object at 0x0000012DE7331DA0>, 'Connection to api.telegram.org timed out. (connect timeout=5.0)')': /bot822102958:AAHsgSxtLNp1FHMFXih30Rkpkx4DHFsvsFU/getUpdates
2019-11-02 12:20:20,594 - WARNING - Retrying (Retry(total=1, connect=None, read=None, redirect=None)) after connection broken by 'ConnectTimeoutError(<telegram.vendor.ptb_urllib3.urllib3.connection.VerifiedHTTPSConnection object at 0x0000012DE7331AC8>, 'Connection to api.telegram.org timed out. (connect timeout=5.0)')': /bot822102958:AAHsgSxtLNp1FHMFXih30Rkpkx4DHFsvsFU/getUpdates
2019-11-02 12:20:25,595 - WARNING - Retrying (Retry(total=0, connect=None, read=None, redirect=None)) after connection broken by 'ConnectTimeoutError(<telegram.vendor.ptb_urllib3.urllib3.connection.VerifiedHTTPSConnection object at 0x0000012DE7331BE0>, 'Connection to api.telegram.org timed out. (connect timeout=5.0)')': /bot822102958:AAHsgSxtLNp1FHMFXih30Rkpkx4DHFsvsFU/getUpdates
2019-11-02 12:20:30,597 - ERROR - Error while getting Updates: urllib3 HTTPError HTTPSConnectionPool(host='api.telegram.org', port=443): Max retries exceeded with url: /bot822102958:AAHsgSxtLNp1FHMFXih30Rkpkx4DHFsvsFU/getUpdates (Caused by ConnectTimeoutError(<telegram.vendor.ptb_urllib3.urllib3.connection.VerifiedHTTPSConnection object at 0x0000012DE7C48B38>, 'Connection to api.telegram.org timed out. (connect timeout=5.0)'))
2019-11-02 12:20:30,597 - ERROR - No error handlers are registered, logging exception.
Traceback (most recent call last):
  File "c:\projects\next_bot\env\lib\site-packages\telegram\vendor\ptb_urllib3\urllib3\connection.py", line 141, in _new_conn
    (self.host, self.port), self.timeout, **extra_kw)
  File "c:\projects\next_bot\env\lib\site-packages\telegram\vendor\ptb_urllib3\urllib3\util\connection.py", line 83, in create_connection
    raise err
  File "c:\projects\next_bot\env\lib\site-packages\telegram\vendor\ptb_urllib3\urllib3\util\connection.py", line 73, in create_connection
    sock.connect(sa)
socket.timeout: timed out

During handling of the above exception, another exception occurred:

Traceback (most recent call last):
  File "c:\projects\next_bot\env\lib\site-packages\telegram\vendor\ptb_urllib3\urllib3\connectionpool.py", line 617, in urlopen
    chunked=chunked)
  File "c:\projects\next_bot\env\lib\site-packages\telegram\vendor\ptb_urllib3\urllib3\connectionpool.py", line 360, in _make_request
    self._validate_conn(conn)
  File "c:\projects\next_bot\env\lib\site-packages\telegram\vendor\ptb_urllib3\urllib3\connectionpool.py", line 857, in _validate_conn
    super(HTTPSConnectionPool, self)._validate_conn(conn)
  File "c:\projects\next_bot\env\lib\site-packages\telegram\vendor\ptb_urllib3\urllib3\connectionpool.py", line 289, in _validate_conn
    conn.connect()
  File "c:\projects\next_bot\env\lib\site-packages\telegram\vendor\ptb_urllib3\urllib3\connection.py", line 284, in connect
    conn = self._new_conn()
  File "c:\projects\next_bot\env\lib\site-packages\telegram\vendor\ptb_urllib3\urllib3\connection.py", line 146, in _new_conn
    (self.host, self.timeout))
telegram.vendor.ptb_urllib3.urllib3.exceptions.ConnectTimeoutError: (<telegram.vendor.ptb_urllib3.urllib3.connection.VerifiedHTTPSConnection object at 0x0000012DE7C48B38>, 'Connection to api.telegram.org timed out. (connect timeout=5.0)')

During handling of the above exception, another exception occurred:

Traceback (most recent call last):
  File "c:\projects\next_bot\env\lib\site-packages\telegram\utils\request.py", line 218, in _request_wrapper
    resp = self._con_pool.request(*args, **kwargs)
  File "c:\projects\next_bot\env\lib\site-packages\telegram\vendor\ptb_urllib3\urllib3\request.py", line 70, in request
    **urlopen_kw)
  File "c:\projects\next_bot\env\lib\site-packages\telegram\vendor\ptb_urllib3\urllib3\request.py", line 148, in request_encode_body
    return self.urlopen(method, url, **extra_kw)
  File "c:\projects\next_bot\env\lib\site-packages\telegram\vendor\ptb_urllib3\urllib3\poolmanager.py", line 244, in urlopen
    response = conn.urlopen(method, u.request_uri, **kw)
  File "c:\projects\next_bot\env\lib\site-packages\telegram\vendor\ptb_urllib3\urllib3\connectionpool.py", line 695, in urlopen
    **response_kw)
  File "c:\projects\next_bot\env\lib\site-packages\telegram\vendor\ptb_urllib3\urllib3\connectionpool.py", line 695, in urlopen
    **response_kw)
  File "c:\projects\next_bot\env\lib\site-packages\telegram\vendor\ptb_urllib3\urllib3\connectionpool.py", line 695, in urlopen
    **response_kw)
  File "c:\projects\next_bot\env\lib\site-packages\telegram\vendor\ptb_urllib3\urllib3\connectionpool.py", line 666, in urlopen
    _stacktrace=sys.exc_info()[2])
  File "c:\projects\next_bot\env\lib\site-packages\telegram\vendor\ptb_urllib3\urllib3\util\retry.py", line 376, in increment
    raise MaxRetryError(_pool, url, error or ResponseError(cause))
telegram.vendor.ptb_urllib3.urllib3.exceptions.MaxRetryError: HTTPSConnectionPool(host='api.telegram.org', port=443): Max retries exceeded with url: /bot822102958:AAHsgSxtLNp1FHMFXih30Rkpkx4DHFsvsFU/getUpdates (Caused by ConnectTimeoutError(<telegram.vendor.ptb_urllib3.urllib3.connection.VerifiedHTTPSConnection object at 0x0000012DE7C48B38>, 'Connection to api.telegram.org timed out. (connect timeout=5.0)'))

During handling of the above exception, another exception occurred:

Traceback (most recent call last):
  File "c:\projects\next_bot\env\lib\site-packages\telegram\ext\updater.py", line 332, in _network_loop_retry
    if not action_cb():
  File "c:\projects\next_bot\env\lib\site-packages\telegram\ext\updater.py", line 293, in polling_action_cb
    allowed_updates=allowed_updates)
  File "c:\projects\next_bot\env\lib\site-packages\telegram\bot.py", line 66, in decorator
    result = func(self, *args, **kwargs)
  File "c:\projects\next_bot\env\lib\site-packages\telegram\bot.py", line 1983, in get_updates
    result = self._request.post(url, data, timeout=float(read_latency) + float(timeout))
  File "c:\projects\next_bot\env\lib\site-packages\telegram\utils\request.py", line 327, in post
    **urlopen_kwargs)
  File "c:\projects\next_bot\env\lib\site-packages\telegram\utils\request.py", line 224, in _request_wrapper
    raise NetworkError('urllib3 HTTPError {0}'.format(error))
telegram.error.NetworkError: urllib3 HTTPError HTTPSConnectionPool(host='api.telegram.org', port=443): Max retries exceeded with url: /bot822102958:AAHsgSxtLNp1FHMFXih30Rkpkx4DHFsvsFU/getUpdates (Caused by ConnectTimeoutError(<telegram.vendor.ptb_urllib3.urllib3.connection.VerifiedHTTPSConnection object at 0x0000012DE7C48B38>, 'Connection to api.telegram.org timed out. (connect timeout=5.0)'))
2019-11-02 12:20:40,662 - WARNING - Retrying (Retry(total=2, connect=None, read=None, redirect=None)) after connection broken by 'ConnectTimeoutError(<telegram.vendor.ptb_urllib3.urllib3.connection.VerifiedHTTPSConnection object at 0x0000012DE7C48278>, 'Connection to api.telegram.org timed out. (connect timeout=5.0)')': /bot822102958:AAHsgSxtLNp1FHMFXih30Rkpkx4DHFsvsFU/getUpdates
2019-11-02 12:20:45,664 - WARNING - Retrying (Retry(total=1, connect=None, read=None, redirect=None)) after connection broken by 'ConnectTimeoutError(<telegram.vendor.ptb_urllib3.urllib3.connection.VerifiedHTTPSConnection object at 0x0000012DE7C48BE0>, 'Connection to api.telegram.org timed out. (connect timeout=5.0)')': /bot822102958:AAHsgSxtLNp1FHMFXih30Rkpkx4DHFsvsFU/getUpdates
2019-11-02 12:20:50,664 - WARNING - Retrying (Retry(total=0, connect=None, read=None, redirect=None)) after connection broken by 'ConnectTimeoutError(<telegram.vendor.ptb_urllib3.urllib3.connection.VerifiedHTTPSConnection object at 0x0000012DE7C48CC0>, 'Connection to api.telegram.org timed out. (connect timeout=5.0)')': /bot822102958:AAHsgSxtLNp1FHMFXih30Rkpkx4DHFsvsFU/getUpdates
2019-11-02 12:20:55,666 - ERROR - Error while getting Updates: urllib3 HTTPError HTTPSConnectionPool(host='api.telegram.org', port=443): Max retries exceeded with url: /bot822102958:AAHsgSxtLNp1FHMFXih30Rkpkx4DHFsvsFU/getUpdates (Caused by ConnectTimeoutError(<telegram.vendor.ptb_urllib3.urllib3.connection.VerifiedHTTPSConnection object at 0x0000012DE7C48DA0>, 'Connection to api.telegram.org timed out. (connect timeout=5.0)'))
2019-11-02 12:20:55,666 - ERROR - No error handlers are registered, logging exception.
Traceback (most recent call last):
  File "c:\projects\next_bot\env\lib\site-packages\telegram\vendor\ptb_urllib3\urllib3\connection.py", line 141, in _new_conn
    (self.host, self.port), self.timeout, **extra_kw)
  File "c:\projects\next_bot\env\lib\site-packages\telegram\vendor\ptb_urllib3\urllib3\util\connection.py", line 83, in create_connection
    raise err
  File "c:\projects\next_bot\env\lib\site-packages\telegram\vendor\ptb_urllib3\urllib3\util\connection.py", line 73, in create_connection
    sock.connect(sa)
socket.timeout: timed out

During handling of the above exception, another exception occurred:

Traceback (most recent call last):
  File "c:\projects\next_bot\env\lib\site-packages\telegram\vendor\ptb_urllib3\urllib3\connectionpool.py", line 617, in urlopen
    chunked=chunked)
  File "c:\projects\next_bot\env\lib\site-packages\telegram\vendor\ptb_urllib3\urllib3\connectionpool.py", line 360, in _make_request
    self._validate_conn(conn)
  File "c:\projects\next_bot\env\lib\site-packages\telegram\vendor\ptb_urllib3\urllib3\connectionpool.py", line 857, in _validate_conn
    super(HTTPSConnectionPool, self)._validate_conn(conn)
  File "c:\projects\next_bot\env\lib\site-packages\telegram\vendor\ptb_urllib3\urllib3\connectionpool.py", line 289, in _validate_conn
    conn.connect()
  File "c:\projects\next_bot\env\lib\site-packages\telegram\vendor\ptb_urllib3\urllib3\connection.py", line 284, in connect
    conn = self._new_conn()
  File "c:\projects\next_bot\env\lib\site-packages\telegram\vendor\ptb_urllib3\urllib3\connection.py", line 146, in _new_conn
    (self.host, self.timeout))
telegram.vendor.ptb_urllib3.urllib3.exceptions.ConnectTimeoutError: (<telegram.vendor.ptb_urllib3.urllib3.connection.VerifiedHTTPSConnection object at 0x0000012DE7C48DA0>, 'Connection to api.telegram.org timed out. (connect timeout=5.0)')

During handling of the above exception, another exception occurred:

Traceback (most recent call last):
  File "c:\projects\next_bot\env\lib\site-packages\telegram\utils\request.py", line 218, in _request_wrapper
    resp = self._con_pool.request(*args, **kwargs)
  File "c:\projects\next_bot\env\lib\site-packages\telegram\vendor\ptb_urllib3\urllib3\request.py", line 70, in request
    **urlopen_kw)
  File "c:\projects\next_bot\env\lib\site-packages\telegram\vendor\ptb_urllib3\urllib3\request.py", line 148, in request_encode_body
    return self.urlopen(method, url, **extra_kw)
  File "c:\projects\next_bot\env\lib\site-packages\telegram\vendor\ptb_urllib3\urllib3\poolmanager.py", line 244, in urlopen
    response = conn.urlopen(method, u.request_uri, **kw)
  File "c:\projects\next_bot\env\lib\site-packages\telegram\vendor\ptb_urllib3\urllib3\connectionpool.py", line 695, in urlopen
    **response_kw)
  File "c:\projects\next_bot\env\lib\site-packages\telegram\vendor\ptb_urllib3\urllib3\connectionpool.py", line 695, in urlopen
    **response_kw)
  File "c:\projects\next_bot\env\lib\site-packages\telegram\vendor\ptb_urllib3\urllib3\connectionpool.py", line 695, in urlopen
    **response_kw)
  File "c:\projects\next_bot\env\lib\site-packages\telegram\vendor\ptb_urllib3\urllib3\connectionpool.py", line 666, in urlopen
    _stacktrace=sys.exc_info()[2])
  File "c:\projects\next_bot\env\lib\site-packages\telegram\vendor\ptb_urllib3\urllib3\util\retry.py", line 376, in increment
    raise MaxRetryError(_pool, url, error or ResponseError(cause))
telegram.vendor.ptb_urllib3.urllib3.exceptions.MaxRetryError: HTTPSConnectionPool(host='api.telegram.org', port=443): Max retries exceeded with url: /bot822102958:AAHsgSxtLNp1FHMFXih30Rkpkx4DHFsvsFU/getUpdates (Caused by ConnectTimeoutError(<telegram.vendor.ptb_urllib3.urllib3.connection.VerifiedHTTPSConnection object at 0x0000012DE7C48DA0>, 'Connection to api.telegram.org timed out. (connect timeout=5.0)'))

During handling of the above exception, another exception occurred:

Traceback (most recent call last):
  File "c:\projects\next_bot\env\lib\site-packages\telegram\ext\updater.py", line 332, in _network_loop_retry
    if not action_cb():
  File "c:\projects\next_bot\env\lib\site-packages\telegram\ext\updater.py", line 293, in polling_action_cb
    allowed_updates=allowed_updates)
  File "c:\projects\next_bot\env\lib\site-packages\telegram\bot.py", line 66, in decorator
    result = func(self, *args, **kwargs)
  File "c:\projects\next_bot\env\lib\site-packages\telegram\bot.py", line 1983, in get_updates
    result = self._request.post(url, data, timeout=float(read_latency) + float(timeout))
  File "c:\projects\next_bot\env\lib\site-packages\telegram\utils\request.py", line 327, in post
    **urlopen_kwargs)
  File "c:\projects\next_bot\env\lib\site-packages\telegram\utils\request.py", line 224, in _request_wrapper
    raise NetworkError('urllib3 HTTPError {0}'.format(error))
telegram.error.NetworkError: urllib3 HTTPError HTTPSConnectionPool(host='api.telegram.org', port=443): Max retries exceeded with url: /bot822102958:AAHsgSxtLNp1FHMFXih30Rkpkx4DHFsvsFU/getUpdates (Caused by ConnectTimeoutError(<telegram.vendor.ptb_urllib3.urllib3.connection.VerifiedHTTPSConnection object at 0x0000012DE7C48DA0>, 'Connection to api.telegram.org timed out. (connect timeout=5.0)'))
2019-11-02 12:21:08,262 - WARNING - Retrying (Retry(total=2, connect=None, read=None, redirect=None)) after connection broken by 'ConnectTimeoutError(<telegram.vendor.ptb_urllib3.urllib3.connection.VerifiedHTTPSConnection object at 0x0000012DE7C48B00>, 'Connection to api.telegram.org timed out. (connect timeout=5.0)')': /bot822102958:AAHsgSxtLNp1FHMFXih30Rkpkx4DHFsvsFU/getUpdates
2019-11-02 12:21:13,264 - WARNING - Retrying (Retry(total=1, connect=None, read=None, redirect=None)) after connection broken by 'ConnectTimeoutError(<telegram.vendor.ptb_urllib3.urllib3.connection.VerifiedHTTPSConnection object at 0x0000012DE7C63080>, 'Connection to api.telegram.org timed out. (connect timeout=5.0)')': /bot822102958:AAHsgSxtLNp1FHMFXih30Rkpkx4DHFsvsFU/getUpdates
2019-11-02 12:21:18,265 - WARNING - Retrying (Retry(total=0, connect=None, read=None, redirect=None)) after connection broken by 'ConnectTimeoutError(<telegram.vendor.ptb_urllib3.urllib3.connection.VerifiedHTTPSConnection object at 0x0000012DE7C63160>, 'Connection to api.telegram.org timed out. (connect timeout=5.0)')': /bot822102958:AAHsgSxtLNp1FHMFXih30Rkpkx4DHFsvsFU/getUpdates
2019-11-02 12:21:23,266 - ERROR - Error while getting Updates: urllib3 HTTPError HTTPSConnectionPool(host='api.telegram.org', port=443): Max retries exceeded with url: /bot822102958:AAHsgSxtLNp1FHMFXih30Rkpkx4DHFsvsFU/getUpdates (Caused by ConnectTimeoutError(<telegram.vendor.ptb_urllib3.urllib3.connection.VerifiedHTTPSConnection object at 0x0000012DE7C63240>, 'Connection to api.telegram.org timed out. (connect timeout=5.0)'))
2019-11-02 12:21:23,266 - ERROR - No error handlers are registered, logging exception.
Traceback (most recent call last):
  File "c:\projects\next_bot\env\lib\site-packages\telegram\vendor\ptb_urllib3\urllib3\connection.py", line 141, in _new_conn
    (self.host, self.port), self.timeout, **extra_kw)
  File "c:\projects\next_bot\env\lib\site-packages\telegram\vendor\ptb_urllib3\urllib3\util\connection.py", line 83, in create_connection
    raise err
  File "c:\projects\next_bot\env\lib\site-packages\telegram\vendor\ptb_urllib3\urllib3\util\connection.py", line 73, in create_connection
    sock.connect(sa)
socket.timeout: timed out

During handling of the above exception, another exception occurred:

Traceback (most recent call last):
  File "c:\projects\next_bot\env\lib\site-packages\telegram\vendor\ptb_urllib3\urllib3\connectionpool.py", line 617, in urlopen
    chunked=chunked)
  File "c:\projects\next_bot\env\lib\site-packages\telegram\vendor\ptb_urllib3\urllib3\connectionpool.py", line 360, in _make_request
    self._validate_conn(conn)
  File "c:\projects\next_bot\env\lib\site-packages\telegram\vendor\ptb_urllib3\urllib3\connectionpool.py", line 857, in _validate_conn
    super(HTTPSConnectionPool, self)._validate_conn(conn)
  File "c:\projects\next_bot\env\lib\site-packages\telegram\vendor\ptb_urllib3\urllib3\connectionpool.py", line 289, in _validate_conn
    conn.connect()
  File "c:\projects\next_bot\env\lib\site-packages\telegram\vendor\ptb_urllib3\urllib3\connection.py", line 284, in connect
    conn = self._new_conn()
  File "c:\projects\next_bot\env\lib\site-packages\telegram\vendor\ptb_urllib3\urllib3\connection.py", line 146, in _new_conn
    (self.host, self.timeout))
telegram.vendor.ptb_urllib3.urllib3.exceptions.ConnectTimeoutError: (<telegram.vendor.ptb_urllib3.urllib3.connection.VerifiedHTTPSConnection object at 0x0000012DE7C63240>, 'Connection to api.telegram.org timed out. (connect timeout=5.0)')

During handling of the above exception, another exception occurred:

Traceback (most recent call last):
  File "c:\projects\next_bot\env\lib\site-packages\telegram\utils\request.py", line 218, in _request_wrapper
    resp = self._con_pool.request(*args, **kwargs)
  File "c:\projects\next_bot\env\lib\site-packages\telegram\vendor\ptb_urllib3\urllib3\request.py", line 70, in request
    **urlopen_kw)
  File "c:\projects\next_bot\env\lib\site-packages\telegram\vendor\ptb_urllib3\urllib3\request.py", line 148, in request_encode_body
    return self.urlopen(method, url, **extra_kw)
  File "c:\projects\next_bot\env\lib\site-packages\telegram\vendor\ptb_urllib3\urllib3\poolmanager.py", line 244, in urlopen
    response = conn.urlopen(method, u.request_uri, **kw)
  File "c:\projects\next_bot\env\lib\site-packages\telegram\vendor\ptb_urllib3\urllib3\connectionpool.py", line 695, in urlopen
    **response_kw)
  File "c:\projects\next_bot\env\lib\site-packages\telegram\vendor\ptb_urllib3\urllib3\connectionpool.py", line 695, in urlopen
    **response_kw)
  File "c:\projects\next_bot\env\lib\site-packages\telegram\vendor\ptb_urllib3\urllib3\connectionpool.py", line 695, in urlopen
    **response_kw)
  File "c:\projects\next_bot\env\lib\site-packages\telegram\vendor\ptb_urllib3\urllib3\connectionpool.py", line 666, in urlopen
    _stacktrace=sys.exc_info()[2])
  File "c:\projects\next_bot\env\lib\site-packages\telegram\vendor\ptb_urllib3\urllib3\util\retry.py", line 376, in increment
    raise MaxRetryError(_pool, url, error or ResponseError(cause))
telegram.vendor.ptb_urllib3.urllib3.exceptions.MaxRetryError: HTTPSConnectionPool(host='api.telegram.org', port=443): Max retries exceeded with url: /bot822102958:AAHsgSxtLNp1FHMFXih30Rkpkx4DHFsvsFU/getUpdates (Caused by ConnectTimeoutError(<telegram.vendor.ptb_urllib3.urllib3.connection.VerifiedHTTPSConnection object at 0x0000012DE7C63240>, 'Connection to api.telegram.org timed out. (connect timeout=5.0)'))

During handling of the above exception, another exception occurred:

Traceback (most recent call last):
  File "c:\projects\next_bot\env\lib\site-packages\telegram\ext\updater.py", line 332, in _network_loop_retry
    if not action_cb():
  File "c:\projects\next_bot\env\lib\site-packages\telegram\ext\updater.py", line 293, in polling_action_cb
    allowed_updates=allowed_updates)
  File "c:\projects\next_bot\env\lib\site-packages\telegram\bot.py", line 66, in decorator
    result = func(self, *args, **kwargs)
  File "c:\projects\next_bot\env\lib\site-packages\telegram\bot.py", line 1983, in get_updates
    result = self._request.post(url, data, timeout=float(read_latency) + float(timeout))
  File "c:\projects\next_bot\env\lib\site-packages\telegram\utils\request.py", line 327, in post
    **urlopen_kwargs)
  File "c:\projects\next_bot\env\lib\site-packages\telegram\utils\request.py", line 224, in _request_wrapper
    raise NetworkError('urllib3 HTTPError {0}'.format(error))
telegram.error.NetworkError: urllib3 HTTPError HTTPSConnectionPool(host='api.telegram.org', port=443): Max retries exceeded with url: /bot822102958:AAHsgSxtLNp1FHMFXih30Rkpkx4DHFsvsFU/getUpdates (Caused by ConnectTimeoutError(<telegram.vendor.ptb_urllib3.urllib3.connection.VerifiedHTTPSConnection object at 0x0000012DE7C63240>, 'Connection to api.telegram.org timed out. (connect timeout=5.0)'))
2019-11-02 12:21:39,659 - WARNING - Retrying (Retry(total=2, connect=None, read=None, redirect=None)) after connection broken by 'ConnectTimeoutError(<telegram.vendor.ptb_urllib3.urllib3.connection.VerifiedHTTPSConnection object at 0x0000012DE7C63470>, 'Connection to api.telegram.org timed out. (connect timeout=5.0)')': /bot822102958:AAHsgSxtLNp1FHMFXih30Rkpkx4DHFsvsFU/getUpdates
2019-11-02 12:21:44,660 - WARNING - Retrying (Retry(total=1, connect=None, read=None, redirect=None)) after connection broken by 'ConnectTimeoutError(<telegram.vendor.ptb_urllib3.urllib3.connection.VerifiedHTTPSConnection object at 0x0000012DE7C635F8>, 'Connection to api.telegram.org timed out. (connect timeout=5.0)')': /bot822102958:AAHsgSxtLNp1FHMFXih30Rkpkx4DHFsvsFU/getUpdates
2019-11-02 12:21:49,662 - WARNING - Retrying (Retry(total=0, connect=None, read=None, redirect=None)) after connection broken by 'ConnectTimeoutError(<telegram.vendor.ptb_urllib3.urllib3.connection.VerifiedHTTPSConnection object at 0x0000012DE7C636D8>, 'Connection to api.telegram.org timed out. (connect timeout=5.0)')': /bot822102958:AAHsgSxtLNp1FHMFXih30Rkpkx4DHFsvsFU/getUpdates
2019-11-02 12:21:54,663 - ERROR - Error while getting Updates: urllib3 HTTPError HTTPSConnectionPool(host='api.telegram.org', port=443): Max retries exceeded with url: /bot822102958:AAHsgSxtLNp1FHMFXih30Rkpkx4DHFsvsFU/getUpdates (Caused by ConnectTimeoutError(<telegram.vendor.ptb_urllib3.urllib3.connection.VerifiedHTTPSConnection object at 0x0000012DE7C637F0>, 'Connection to api.telegram.org timed out. (connect timeout=5.0)'))
2019-11-02 12:21:54,663 - ERROR - No error handlers are registered, logging exception.
Traceback (most recent call last):
  File "c:\projects\next_bot\env\lib\site-packages\telegram\vendor\ptb_urllib3\urllib3\connection.py", line 141, in _new_conn
    (self.host, self.port), self.timeout, **extra_kw)
  File "c:\projects\next_bot\env\lib\site-packages\telegram\vendor\ptb_urllib3\urllib3\util\connection.py", line 83, in create_connection
    raise err
  File "c:\projects\next_bot\env\lib\site-packages\telegram\vendor\ptb_urllib3\urllib3\util\connection.py", line 73, in create_connection
    sock.connect(sa)
socket.timeout: timed out

During handling of the above exception, another exception occurred:

Traceback (most recent call last):
  File "c:\projects\next_bot\env\lib\site-packages\telegram\vendor\ptb_urllib3\urllib3\connectionpool.py", line 617, in urlopen
    chunked=chunked)
  File "c:\projects\next_bot\env\lib\site-packages\telegram\vendor\ptb_urllib3\urllib3\connectionpool.py", line 360, in _make_request
    self._validate_conn(conn)
  File "c:\projects\next_bot\env\lib\site-packages\telegram\vendor\ptb_urllib3\urllib3\connectionpool.py", line 857, in _validate_conn
    super(HTTPSConnectionPool, self)._validate_conn(conn)
  File "c:\projects\next_bot\env\lib\site-packages\telegram\vendor\ptb_urllib3\urllib3\connectionpool.py", line 289, in _validate_conn
    conn.connect()
  File "c:\projects\next_bot\env\lib\site-packages\telegram\vendor\ptb_urllib3\urllib3\connection.py", line 284, in connect
    conn = self._new_conn()
  File "c:\projects\next_bot\env\lib\site-packages\telegram\vendor\ptb_urllib3\urllib3\connection.py", line 146, in _new_conn
    (self.host, self.timeout))
telegram.vendor.ptb_urllib3.urllib3.exceptions.ConnectTimeoutError: (<telegram.vendor.ptb_urllib3.urllib3.connection.VerifiedHTTPSConnection object at 0x0000012DE7C637F0>, 'Connection to api.telegram.org timed out. (connect timeout=5.0)')

During handling of the above exception, another exception occurred:

Traceback (most recent call last):
  File "c:\projects\next_bot\env\lib\site-packages\telegram\utils\request.py", line 218, in _request_wrapper
    resp = self._con_pool.request(*args, **kwargs)
  File "c:\projects\next_bot\env\lib\site-packages\telegram\vendor\ptb_urllib3\urllib3\request.py", line 70, in request
    **urlopen_kw)
  File "c:\projects\next_bot\env\lib\site-packages\telegram\vendor\ptb_urllib3\urllib3\request.py", line 148, in request_encode_body
    return self.urlopen(method, url, **extra_kw)
  File "c:\projects\next_bot\env\lib\site-packages\telegram\vendor\ptb_urllib3\urllib3\poolmanager.py", line 244, in urlopen
    response = conn.urlopen(method, u.request_uri, **kw)
  File "c:\projects\next_bot\env\lib\site-packages\telegram\vendor\ptb_urllib3\urllib3\connectionpool.py", line 695, in urlopen
    **response_kw)
  File "c:\projects\next_bot\env\lib\site-packages\telegram\vendor\ptb_urllib3\urllib3\connectionpool.py", line 695, in urlopen
    **response_kw)
  File "c:\projects\next_bot\env\lib\site-packages\telegram\vendor\ptb_urllib3\urllib3\connectionpool.py", line 695, in urlopen
    **response_kw)
  File "c:\projects\next_bot\env\lib\site-packages\telegram\vendor\ptb_urllib3\urllib3\connectionpool.py", line 666, in urlopen
    _stacktrace=sys.exc_info()[2])
  File "c:\projects\next_bot\env\lib\site-packages\telegram\vendor\ptb_urllib3\urllib3\util\retry.py", line 376, in increment
    raise MaxRetryError(_pool, url, error or ResponseError(cause))
telegram.vendor.ptb_urllib3.urllib3.exceptions.MaxRetryError: HTTPSConnectionPool(host='api.telegram.org', port=443): Max retries exceeded with url: /bot822102958:AAHsgSxtLNp1FHMFXih30Rkpkx4DHFsvsFU/getUpdates (Caused by ConnectTimeoutError(<telegram.vendor.ptb_urllib3.urllib3.connection.VerifiedHTTPSConnection object at 0x0000012DE7C637F0>, 'Connection to api.telegram.org timed out. (connect timeout=5.0)'))

During handling of the above exception, another exception occurred:

Traceback (most recent call last):
  File "c:\projects\next_bot\env\lib\site-packages\telegram\ext\updater.py", line 332, in _network_loop_retry
    if not action_cb():
  File "c:\projects\next_bot\env\lib\site-packages\telegram\ext\updater.py", line 293, in polling_action_cb
    allowed_updates=allowed_updates)
  File "c:\projects\next_bot\env\lib\site-packages\telegram\bot.py", line 66, in decorator
    result = func(self, *args, **kwargs)
  File "c:\projects\next_bot\env\lib\site-packages\telegram\bot.py", line 1983, in get_updates
    result = self._request.post(url, data, timeout=float(read_latency) + float(timeout))
  File "c:\projects\next_bot\env\lib\site-packages\telegram\utils\request.py", line 327, in post
    **urlopen_kwargs)
  File "c:\projects\next_bot\env\lib\site-packages\telegram\utils\request.py", line 224, in _request_wrapper
    raise NetworkError('urllib3 HTTPError {0}'.format(error))
telegram.error.NetworkError: urllib3 HTTPError HTTPSConnectionPool(host='api.telegram.org', port=443): Max retries exceeded with url: /bot822102958:AAHsgSxtLNp1FHMFXih30Rkpkx4DHFsvsFU/getUpdates (Caused by ConnectTimeoutError(<telegram.vendor.ptb_urllib3.urllib3.connection.VerifiedHTTPSConnection object at 0x0000012DE7C637F0>, 'Connection to api.telegram.org timed out. (connect timeout=5.0)'))
2019-11-02 12:22:16,751 - WARNING - Retrying (Retry(total=2, connect=None, read=None, redirect=None)) after connection broken by 'ConnectTimeoutError(<telegram.vendor.ptb_urllib3.urllib3.connection.VerifiedHTTPSConnection object at 0x0000012DE7C63390>, 'Connection to api.telegram.org timed out. (connect timeout=5.0)')': /bot822102958:AAHsgSxtLNp1FHMFXih30Rkpkx4DHFsvsFU/getUpdates
2019-11-02 12:22:21,753 - WARNING - Retrying (Retry(total=1, connect=None, read=None, redirect=None)) after connection broken by 'ConnectTimeoutError(<telegram.vendor.ptb_urllib3.urllib3.connection.VerifiedHTTPSConnection object at 0x0000012DE7C63BA8>, 'Connection to api.telegram.org timed out. (connect timeout=5.0)')': /bot822102958:AAHsgSxtLNp1FHMFXih30Rkpkx4DHFsvsFU/getUpdates
2019-11-02 12:22:26,754 - WARNING - Retrying (Retry(total=0, connect=None, read=None, redirect=None)) after connection broken by 'ConnectTimeoutError(<telegram.vendor.ptb_urllib3.urllib3.connection.VerifiedHTTPSConnection object at 0x0000012DE7C63C88>, 'Connection to api.telegram.org timed out. (connect timeout=5.0)')': /bot822102958:AAHsgSxtLNp1FHMFXih30Rkpkx4DHFsvsFU/getUpdates
2019-11-02 12:22:31,755 - ERROR - Error while getting Updates: urllib3 HTTPError HTTPSConnectionPool(host='api.telegram.org', port=443): Max retries exceeded with url: /bot822102958:AAHsgSxtLNp1FHMFXih30Rkpkx4DHFsvsFU/getUpdates (Caused by ConnectTimeoutError(<telegram.vendor.ptb_urllib3.urllib3.connection.VerifiedHTTPSConnection object at 0x0000012DE7C63DA0>, 'Connection to api.telegram.org timed out. (connect timeout=5.0)'))
2019-11-02 12:22:31,755 - ERROR - No error handlers are registered, logging exception.
Traceback (most recent call last):
  File "c:\projects\next_bot\env\lib\site-packages\telegram\vendor\ptb_urllib3\urllib3\connection.py", line 141, in _new_conn
    (self.host, self.port), self.timeout, **extra_kw)
  File "c:\projects\next_bot\env\lib\site-packages\telegram\vendor\ptb_urllib3\urllib3\util\connection.py", line 83, in create_connection
    raise err
  File "c:\projects\next_bot\env\lib\site-packages\telegram\vendor\ptb_urllib3\urllib3\util\connection.py", line 73, in create_connection
    sock.connect(sa)
socket.timeout: timed out

During handling of the above exception, another exception occurred:

Traceback (most recent call last):
  File "c:\projects\next_bot\env\lib\site-packages\telegram\vendor\ptb_urllib3\urllib3\connectionpool.py", line 617, in urlopen
    chunked=chunked)
  File "c:\projects\next_bot\env\lib\site-packages\telegram\vendor\ptb_urllib3\urllib3\connectionpool.py", line 360, in _make_request
    self._validate_conn(conn)
  File "c:\projects\next_bot\env\lib\site-packages\telegram\vendor\ptb_urllib3\urllib3\connectionpool.py", line 857, in _validate_conn
    super(HTTPSConnectionPool, self)._validate_conn(conn)
  File "c:\projects\next_bot\env\lib\site-packages\telegram\vendor\ptb_urllib3\urllib3\connectionpool.py", line 289, in _validate_conn
    conn.connect()
  File "c:\projects\next_bot\env\lib\site-packages\telegram\vendor\ptb_urllib3\urllib3\connection.py", line 284, in connect
    conn = self._new_conn()
  File "c:\projects\next_bot\env\lib\site-packages\telegram\vendor\ptb_urllib3\urllib3\connection.py", line 146, in _new_conn
    (self.host, self.timeout))
telegram.vendor.ptb_urllib3.urllib3.exceptions.ConnectTimeoutError: (<telegram.vendor.ptb_urllib3.urllib3.connection.VerifiedHTTPSConnection object at 0x0000012DE7C63DA0>, 'Connection to api.telegram.org timed out. (connect timeout=5.0)')

During handling of the above exception, another exception occurred:

Traceback (most recent call last):
  File "c:\projects\next_bot\env\lib\site-packages\telegram\utils\request.py", line 218, in _request_wrapper
    resp = self._con_pool.request(*args, **kwargs)
  File "c:\projects\next_bot\env\lib\site-packages\telegram\vendor\ptb_urllib3\urllib3\request.py", line 70, in request
    **urlopen_kw)
  File "c:\projects\next_bot\env\lib\site-packages\telegram\vendor\ptb_urllib3\urllib3\request.py", line 148, in request_encode_body
    return self.urlopen(method, url, **extra_kw)
  File "c:\projects\next_bot\env\lib\site-packages\telegram\vendor\ptb_urllib3\urllib3\poolmanager.py", line 244, in urlopen
    response = conn.urlopen(method, u.request_uri, **kw)
  File "c:\projects\next_bot\env\lib\site-packages\telegram\vendor\ptb_urllib3\urllib3\connectionpool.py", line 695, in urlopen
    **response_kw)
  File "c:\projects\next_bot\env\lib\site-packages\telegram\vendor\ptb_urllib3\urllib3\connectionpool.py", line 695, in urlopen
    **response_kw)
  File "c:\projects\next_bot\env\lib\site-packages\telegram\vendor\ptb_urllib3\urllib3\connectionpool.py", line 695, in urlopen
    **response_kw)
  File "c:\projects\next_bot\env\lib\site-packages\telegram\vendor\ptb_urllib3\urllib3\connectionpool.py", line 666, in urlopen
    _stacktrace=sys.exc_info()[2])
  File "c:\projects\next_bot\env\lib\site-packages\telegram\vendor\ptb_urllib3\urllib3\util\retry.py", line 376, in increment
    raise MaxRetryError(_pool, url, error or ResponseError(cause))
telegram.vendor.ptb_urllib3.urllib3.exceptions.MaxRetryError: HTTPSConnectionPool(host='api.telegram.org', port=443): Max retries exceeded with url: /bot822102958:AAHsgSxtLNp1FHMFXih30Rkpkx4DHFsvsFU/getUpdates (Caused by ConnectTimeoutError(<telegram.vendor.ptb_urllib3.urllib3.connection.VerifiedHTTPSConnection object at 0x0000012DE7C63DA0>, 'Connection to api.telegram.org timed out. (connect timeout=5.0)'))

During handling of the above exception, another exception occurred:

Traceback (most recent call last):
  File "c:\projects\next_bot\env\lib\site-packages\telegram\ext\updater.py", line 332, in _network_loop_retry
    if not action_cb():
  File "c:\projects\next_bot\env\lib\site-packages\telegram\ext\updater.py", line 293, in polling_action_cb
    allowed_updates=allowed_updates)
  File "c:\projects\next_bot\env\lib\site-packages\telegram\bot.py", line 66, in decorator
    result = func(self, *args, **kwargs)
  File "c:\projects\next_bot\env\lib\site-packages\telegram\bot.py", line 1983, in get_updates
    result = self._request.post(url, data, timeout=float(read_latency) + float(timeout))
  File "c:\projects\next_bot\env\lib\site-packages\telegram\utils\request.py", line 327, in post
    **urlopen_kwargs)
  File "c:\projects\next_bot\env\lib\site-packages\telegram\utils\request.py", line 224, in _request_wrapper
    raise NetworkError('urllib3 HTTPError {0}'.format(error))
telegram.error.NetworkError: urllib3 HTTPError HTTPSConnectionPool(host='api.telegram.org', port=443): Max retries exceeded with url: /bot822102958:AAHsgSxtLNp1FHMFXih30Rkpkx4DHFsvsFU/getUpdates (Caused by ConnectTimeoutError(<telegram.vendor.ptb_urllib3.urllib3.connection.VerifiedHTTPSConnection object at 0x0000012DE7C63DA0>, 'Connection to api.telegram.org timed out. (connect timeout=5.0)'))
2019-11-02 12:23:02,386 - WARNING - Retrying (Retry(total=2, connect=None, read=None, redirect=None)) after connection broken by 'ConnectTimeoutError(<telegram.vendor.ptb_urllib3.urllib3.connection.VerifiedHTTPSConnection object at 0x0000012DE7331CF8>, 'Connection to api.telegram.org timed out. (connect timeout=5.0)')': /bot822102958:AAHsgSxtLNp1FHMFXih30Rkpkx4DHFsvsFU/getUpdates
2019-11-02 12:23:07,387 - WARNING - Retrying (Retry(total=1, connect=None, read=None, redirect=None)) after connection broken by 'ConnectTimeoutError(<telegram.vendor.ptb_urllib3.urllib3.connection.VerifiedHTTPSConnection object at 0x0000012DE7331C50>, 'Connection to api.telegram.org timed out. (connect timeout=5.0)')': /bot822102958:AAHsgSxtLNp1FHMFXih30Rkpkx4DHFsvsFU/getUpdates
2019-11-02 12:23:12,388 - WARNING - Retrying (Retry(total=0, connect=None, read=None, redirect=None)) after connection broken by 'ConnectTimeoutError(<telegram.vendor.ptb_urllib3.urllib3.connection.VerifiedHTTPSConnection object at 0x0000012DE7331E10>, 'Connection to api.telegram.org timed out. (connect timeout=5.0)')': /bot822102958:AAHsgSxtLNp1FHMFXih30Rkpkx4DHFsvsFU/getUpdates
2019-11-02 12:23:17,401 - ERROR - Error while getting Updates: urllib3 HTTPError HTTPSConnectionPool(host='api.telegram.org', port=443): Max retries exceeded with url: /bot822102958:AAHsgSxtLNp1FHMFXih30Rkpkx4DHFsvsFU/getUpdates (Caused by ConnectTimeoutError(<telegram.vendor.ptb_urllib3.urllib3.connection.VerifiedHTTPSConnection object at 0x0000012DE735FFD0>, 'Connection to api.telegram.org timed out. (connect timeout=5.0)'))
2019-11-02 12:23:17,401 - ERROR - No error handlers are registered, logging exception.
Traceback (most recent call last):
  File "c:\projects\next_bot\env\lib\site-packages\telegram\vendor\ptb_urllib3\urllib3\connection.py", line 141, in _new_conn
    (self.host, self.port), self.timeout, **extra_kw)
  File "c:\projects\next_bot\env\lib\site-packages\telegram\vendor\ptb_urllib3\urllib3\util\connection.py", line 83, in create_connection
    raise err
  File "c:\projects\next_bot\env\lib\site-packages\telegram\vendor\ptb_urllib3\urllib3\util\connection.py", line 73, in create_connection
    sock.connect(sa)
socket.timeout: timed out

During handling of the above exception, another exception occurred:

Traceback (most recent call last):
  File "c:\projects\next_bot\env\lib\site-packages\telegram\vendor\ptb_urllib3\urllib3\connectionpool.py", line 617, in urlopen
    chunked=chunked)
  File "c:\projects\next_bot\env\lib\site-packages\telegram\vendor\ptb_urllib3\urllib3\connectionpool.py", line 360, in _make_request
    self._validate_conn(conn)
  File "c:\projects\next_bot\env\lib\site-packages\telegram\vendor\ptb_urllib3\urllib3\connectionpool.py", line 857, in _validate_conn
    super(HTTPSConnectionPool, self)._validate_conn(conn)
  File "c:\projects\next_bot\env\lib\site-packages\telegram\vendor\ptb_urllib3\urllib3\connectionpool.py", line 289, in _validate_conn
    conn.connect()
  File "c:\projects\next_bot\env\lib\site-packages\telegram\vendor\ptb_urllib3\urllib3\connection.py", line 284, in connect
    conn = self._new_conn()
  File "c:\projects\next_bot\env\lib\site-packages\telegram\vendor\ptb_urllib3\urllib3\connection.py", line 146, in _new_conn
    (self.host, self.timeout))
telegram.vendor.ptb_urllib3.urllib3.exceptions.ConnectTimeoutError: (<telegram.vendor.ptb_urllib3.urllib3.connection.VerifiedHTTPSConnection object at 0x0000012DE735FFD0>, 'Connection to api.telegram.org timed out. (connect timeout=5.0)')

During handling of the above exception, another exception occurred:

Traceback (most recent call last):
  File "c:\projects\next_bot\env\lib\site-packages\telegram\utils\request.py", line 218, in _request_wrapper
    resp = self._con_pool.request(*args, **kwargs)
  File "c:\projects\next_bot\env\lib\site-packages\telegram\vendor\ptb_urllib3\urllib3\request.py", line 70, in request
    **urlopen_kw)
  File "c:\projects\next_bot\env\lib\site-packages\telegram\vendor\ptb_urllib3\urllib3\request.py", line 148, in request_encode_body
    return self.urlopen(method, url, **extra_kw)
  File "c:\projects\next_bot\env\lib\site-packages\telegram\vendor\ptb_urllib3\urllib3\poolmanager.py", line 244, in urlopen
    response = conn.urlopen(method, u.request_uri, **kw)
  File "c:\projects\next_bot\env\lib\site-packages\telegram\vendor\ptb_urllib3\urllib3\connectionpool.py", line 695, in urlopen
    **response_kw)
  File "c:\projects\next_bot\env\lib\site-packages\telegram\vendor\ptb_urllib3\urllib3\connectionpool.py", line 695, in urlopen
    **response_kw)
  File "c:\projects\next_bot\env\lib\site-packages\telegram\vendor\ptb_urllib3\urllib3\connectionpool.py", line 695, in urlopen
    **response_kw)
  File "c:\projects\next_bot\env\lib\site-packages\telegram\vendor\ptb_urllib3\urllib3\connectionpool.py", line 666, in urlopen
    _stacktrace=sys.exc_info()[2])
  File "c:\projects\next_bot\env\lib\site-packages\telegram\vendor\ptb_urllib3\urllib3\util\retry.py", line 376, in increment
    raise MaxRetryError(_pool, url, error or ResponseError(cause))
telegram.vendor.ptb_urllib3.urllib3.exceptions.MaxRetryError: HTTPSConnectionPool(host='api.telegram.org', port=443): Max retries exceeded with url: /bot822102958:AAHsgSxtLNp1FHMFXih30Rkpkx4DHFsvsFU/getUpdates (Caused by ConnectTimeoutError(<telegram.vendor.ptb_urllib3.urllib3.connection.VerifiedHTTPSConnection object at 0x0000012DE735FFD0>, 'Connection to api.telegram.org timed out. (connect timeout=5.0)'))

During handling of the above exception, another exception occurred:

Traceback (most recent call last):
  File "c:\projects\next_bot\env\lib\site-packages\telegram\ext\updater.py", line 332, in _network_loop_retry
    if not action_cb():
  File "c:\projects\next_bot\env\lib\site-packages\telegram\ext\updater.py", line 293, in polling_action_cb
    allowed_updates=allowed_updates)
  File "c:\projects\next_bot\env\lib\site-packages\telegram\bot.py", line 66, in decorator
    result = func(self, *args, **kwargs)
  File "c:\projects\next_bot\env\lib\site-packages\telegram\bot.py", line 1983, in get_updates
    result = self._request.post(url, data, timeout=float(read_latency) + float(timeout))
  File "c:\projects\next_bot\env\lib\site-packages\telegram\utils\request.py", line 327, in post
    **urlopen_kwargs)
  File "c:\projects\next_bot\env\lib\site-packages\telegram\utils\request.py", line 224, in _request_wrapper
    raise NetworkError('urllib3 HTTPError {0}'.format(error))
telegram.error.NetworkError: urllib3 HTTPError HTTPSConnectionPool(host='api.telegram.org', port=443): Max retries exceeded with url: /bot822102958:AAHsgSxtLNp1FHMFXih30Rkpkx4DHFsvsFU/getUpdates (Caused by ConnectTimeoutError(<telegram.vendor.ptb_urllib3.urllib3.connection.VerifiedHTTPSConnection object at 0x0000012DE735FFD0>, 'Connection to api.telegram.org timed out. (connect timeout=5.0)'))
2019-11-02 12:24:00,848 - WARNING - Retrying (Retry(total=2, connect=None, read=None, redirect=None)) after connection broken by 'ConnectTimeoutError(<telegram.vendor.ptb_urllib3.urllib3.connection.VerifiedHTTPSConnection object at 0x0000012DE7C48A20>, 'Connection to api.telegram.org timed out. (connect timeout=5.0)')': /bot822102958:AAHsgSxtLNp1FHMFXih30Rkpkx4DHFsvsFU/getUpdates
2019-11-02 12:24:05,849 - WARNING - Retrying (Retry(total=1, connect=None, read=None, redirect=None)) after connection broken by 'ConnectTimeoutError(<telegram.vendor.ptb_urllib3.urllib3.connection.VerifiedHTTPSConnection object at 0x0000012DE7C48160>, 'Connection to api.telegram.org timed out. (connect timeout=5.0)')': /bot822102958:AAHsgSxtLNp1FHMFXih30Rkpkx4DHFsvsFU/getUpdates
2019-11-02 12:24:10,851 - WARNING - Retrying (Retry(total=0, connect=None, read=None, redirect=None)) after connection broken by 'ConnectTimeoutError(<telegram.vendor.ptb_urllib3.urllib3.connection.VerifiedHTTPSConnection object at 0x0000012DE7C48BA8>, 'Connection to api.telegram.org timed out. (connect timeout=5.0)')': /bot822102958:AAHsgSxtLNp1FHMFXih30Rkpkx4DHFsvsFU/getUpdates
2019-11-02 12:24:15,852 - ERROR - Error while getting Updates: urllib3 HTTPError HTTPSConnectionPool(host='api.telegram.org', port=443): Max retries exceeded with url: /bot822102958:AAHsgSxtLNp1FHMFXih30Rkpkx4DHFsvsFU/getUpdates (Caused by ConnectTimeoutError(<telegram.vendor.ptb_urllib3.urllib3.connection.VerifiedHTTPSConnection object at 0x0000012DE7C48C18>, 'Connection to api.telegram.org timed out. (connect timeout=5.0)'))
2019-11-02 12:24:15,852 - ERROR - No error handlers are registered, logging exception.
Traceback (most recent call last):
  File "c:\projects\next_bot\env\lib\site-packages\telegram\vendor\ptb_urllib3\urllib3\connection.py", line 141, in _new_conn
    (self.host, self.port), self.timeout, **extra_kw)
  File "c:\projects\next_bot\env\lib\site-packages\telegram\vendor\ptb_urllib3\urllib3\util\connection.py", line 83, in create_connection
    raise err
  File "c:\projects\next_bot\env\lib\site-packages\telegram\vendor\ptb_urllib3\urllib3\util\connection.py", line 73, in create_connection
    sock.connect(sa)
socket.timeout: timed out

During handling of the above exception, another exception occurred:

Traceback (most recent call last):
  File "c:\projects\next_bot\env\lib\site-packages\telegram\vendor\ptb_urllib3\urllib3\connectionpool.py", line 617, in urlopen
    chunked=chunked)
  File "c:\projects\next_bot\env\lib\site-packages\telegram\vendor\ptb_urllib3\urllib3\connectionpool.py", line 360, in _make_request
    self._validate_conn(conn)
  File "c:\projects\next_bot\env\lib\site-packages\telegram\vendor\ptb_urllib3\urllib3\connectionpool.py", line 857, in _validate_conn
    super(HTTPSConnectionPool, self)._validate_conn(conn)
  File "c:\projects\next_bot\env\lib\site-packages\telegram\vendor\ptb_urllib3\urllib3\connectionpool.py", line 289, in _validate_conn
    conn.connect()
  File "c:\projects\next_bot\env\lib\site-packages\telegram\vendor\ptb_urllib3\urllib3\connection.py", line 284, in connect
    conn = self._new_conn()
  File "c:\projects\next_bot\env\lib\site-packages\telegram\vendor\ptb_urllib3\urllib3\connection.py", line 146, in _new_conn
    (self.host, self.timeout))
telegram.vendor.ptb_urllib3.urllib3.exceptions.ConnectTimeoutError: (<telegram.vendor.ptb_urllib3.urllib3.connection.VerifiedHTTPSConnection object at 0x0000012DE7C48C18>, 'Connection to api.telegram.org timed out. (connect timeout=5.0)')

During handling of the above exception, another exception occurred:

Traceback (most recent call last):
  File "c:\projects\next_bot\env\lib\site-packages\telegram\utils\request.py", line 218, in _request_wrapper
    resp = self._con_pool.request(*args, **kwargs)
  File "c:\projects\next_bot\env\lib\site-packages\telegram\vendor\ptb_urllib3\urllib3\request.py", line 70, in request
    **urlopen_kw)
  File "c:\projects\next_bot\env\lib\site-packages\telegram\vendor\ptb_urllib3\urllib3\request.py", line 148, in request_encode_body
    return self.urlopen(method, url, **extra_kw)
  File "c:\projects\next_bot\env\lib\site-packages\telegram\vendor\ptb_urllib3\urllib3\poolmanager.py", line 244, in urlopen
    response = conn.urlopen(method, u.request_uri, **kw)
  File "c:\projects\next_bot\env\lib\site-packages\telegram\vendor\ptb_urllib3\urllib3\connectionpool.py", line 695, in urlopen
    **response_kw)
  File "c:\projects\next_bot\env\lib\site-packages\telegram\vendor\ptb_urllib3\urllib3\connectionpool.py", line 695, in urlopen
    **response_kw)
  File "c:\projects\next_bot\env\lib\site-packages\telegram\vendor\ptb_urllib3\urllib3\connectionpool.py", line 695, in urlopen
    **response_kw)
  File "c:\projects\next_bot\env\lib\site-packages\telegram\vendor\ptb_urllib3\urllib3\connectionpool.py", line 666, in urlopen
    _stacktrace=sys.exc_info()[2])
  File "c:\projects\next_bot\env\lib\site-packages\telegram\vendor\ptb_urllib3\urllib3\util\retry.py", line 376, in increment
    raise MaxRetryError(_pool, url, error or ResponseError(cause))
telegram.vendor.ptb_urllib3.urllib3.exceptions.MaxRetryError: HTTPSConnectionPool(host='api.telegram.org', port=443): Max retries exceeded with url: /bot822102958:AAHsgSxtLNp1FHMFXih30Rkpkx4DHFsvsFU/getUpdates (Caused by ConnectTimeoutError(<telegram.vendor.ptb_urllib3.urllib3.connection.VerifiedHTTPSConnection object at 0x0000012DE7C48C18>, 'Connection to api.telegram.org timed out. (connect timeout=5.0)'))

During handling of the above exception, another exception occurred:

Traceback (most recent call last):
  File "c:\projects\next_bot\env\lib\site-packages\telegram\ext\updater.py", line 332, in _network_loop_retry
    if not action_cb():
  File "c:\projects\next_bot\env\lib\site-packages\telegram\ext\updater.py", line 293, in polling_action_cb
    allowed_updates=allowed_updates)
  File "c:\projects\next_bot\env\lib\site-packages\telegram\bot.py", line 66, in decorator
    result = func(self, *args, **kwargs)
  File "c:\projects\next_bot\env\lib\site-packages\telegram\bot.py", line 1983, in get_updates
    result = self._request.post(url, data, timeout=float(read_latency) + float(timeout))
  File "c:\projects\next_bot\env\lib\site-packages\telegram\utils\request.py", line 327, in post
    **urlopen_kwargs)
  File "c:\projects\next_bot\env\lib\site-packages\telegram\utils\request.py", line 224, in _request_wrapper
    raise NetworkError('urllib3 HTTPError {0}'.format(error))
telegram.error.NetworkError: urllib3 HTTPError HTTPSConnectionPool(host='api.telegram.org', port=443): Max retries exceeded with url: /bot822102958:AAHsgSxtLNp1FHMFXih30Rkpkx4DHFsvsFU/getUpdates (Caused by ConnectTimeoutError(<telegram.vendor.ptb_urllib3.urllib3.connection.VerifiedHTTPSConnection object at 0x0000012DE7C48C18>, 'Connection to api.telegram.org timed out. (connect timeout=5.0)'))
2019-11-02 12:24:50,855 - WARNING - Retrying (Retry(total=2, connect=None, read=None, redirect=None)) after connection broken by 'ConnectTimeoutError(<telegram.vendor.ptb_urllib3.urllib3.connection.VerifiedHTTPSConnection object at 0x0000012DE7C48E80>, 'Connection to api.telegram.org timed out. (connect timeout=5.0)')': /bot822102958:AAHsgSxtLNp1FHMFXih30Rkpkx4DHFsvsFU/getUpdates
2019-11-02 12:24:55,856 - WARNING - Retrying (Retry(total=1, connect=None, read=None, redirect=None)) after connection broken by 'ConnectTimeoutError(<telegram.vendor.ptb_urllib3.urllib3.connection.VerifiedHTTPSConnection object at 0x0000012DE7C48978>, 'Connection to api.telegram.org timed out. (connect timeout=5.0)')': /bot822102958:AAHsgSxtLNp1FHMFXih30Rkpkx4DHFsvsFU/getUpdates
2019-11-02 12:25:00,857 - WARNING - Retrying (Retry(total=0, connect=None, read=None, redirect=None)) after connection broken by 'ConnectTimeoutError(<telegram.vendor.ptb_urllib3.urllib3.connection.VerifiedHTTPSConnection object at 0x0000012DE7C48B70>, 'Connection to api.telegram.org timed out. (connect timeout=5.0)')': /bot822102958:AAHsgSxtLNp1FHMFXih30Rkpkx4DHFsvsFU/getUpdates
2019-11-02 12:25:05,858 - ERROR - Error while getting Updates: urllib3 HTTPError HTTPSConnectionPool(host='api.telegram.org', port=443): Max retries exceeded with url: /bot822102958:AAHsgSxtLNp1FHMFXih30Rkpkx4DHFsvsFU/getUpdates (Caused by ConnectTimeoutError(<telegram.vendor.ptb_urllib3.urllib3.connection.VerifiedHTTPSConnection object at 0x0000012DE7C630F0>, 'Connection to api.telegram.org timed out. (connect timeout=5.0)'))
2019-11-02 12:25:05,859 - ERROR - No error handlers are registered, logging exception.
Traceback (most recent call last):
  File "c:\projects\next_bot\env\lib\site-packages\telegram\vendor\ptb_urllib3\urllib3\connection.py", line 141, in _new_conn
    (self.host, self.port), self.timeout, **extra_kw)
  File "c:\projects\next_bot\env\lib\site-packages\telegram\vendor\ptb_urllib3\urllib3\util\connection.py", line 83, in create_connection
    raise err
  File "c:\projects\next_bot\env\lib\site-packages\telegram\vendor\ptb_urllib3\urllib3\util\connection.py", line 73, in create_connection
    sock.connect(sa)
socket.timeout: timed out

During handling of the above exception, another exception occurred:

Traceback (most recent call last):
  File "c:\projects\next_bot\env\lib\site-packages\telegram\vendor\ptb_urllib3\urllib3\connectionpool.py", line 617, in urlopen
    chunked=chunked)
  File "c:\projects\next_bot\env\lib\site-packages\telegram\vendor\ptb_urllib3\urllib3\connectionpool.py", line 360, in _make_request
    self._validate_conn(conn)
  File "c:\projects\next_bot\env\lib\site-packages\telegram\vendor\ptb_urllib3\urllib3\connectionpool.py", line 857, in _validate_conn
    super(HTTPSConnectionPool, self)._validate_conn(conn)
  File "c:\projects\next_bot\env\lib\site-packages\telegram\vendor\ptb_urllib3\urllib3\connectionpool.py", line 289, in _validate_conn
    conn.connect()
  File "c:\projects\next_bot\env\lib\site-packages\telegram\vendor\ptb_urllib3\urllib3\connection.py", line 284, in connect
    conn = self._new_conn()
  File "c:\projects\next_bot\env\lib\site-packages\telegram\vendor\ptb_urllib3\urllib3\connection.py", line 146, in _new_conn
    (self.host, self.timeout))
telegram.vendor.ptb_urllib3.urllib3.exceptions.ConnectTimeoutError: (<telegram.vendor.ptb_urllib3.urllib3.connection.VerifiedHTTPSConnection object at 0x0000012DE7C630F0>, 'Connection to api.telegram.org timed out. (connect timeout=5.0)')

During handling of the above exception, another exception occurred:

Traceback (most recent call last):
  File "c:\projects\next_bot\env\lib\site-packages\telegram\utils\request.py", line 218, in _request_wrapper
    resp = self._con_pool.request(*args, **kwargs)
  File "c:\projects\next_bot\env\lib\site-packages\telegram\vendor\ptb_urllib3\urllib3\request.py", line 70, in request
    **urlopen_kw)
  File "c:\projects\next_bot\env\lib\site-packages\telegram\vendor\ptb_urllib3\urllib3\request.py", line 148, in request_encode_body
    return self.urlopen(method, url, **extra_kw)
  File "c:\projects\next_bot\env\lib\site-packages\telegram\vendor\ptb_urllib3\urllib3\poolmanager.py", line 244, in urlopen
    response = conn.urlopen(method, u.request_uri, **kw)
  File "c:\projects\next_bot\env\lib\site-packages\telegram\vendor\ptb_urllib3\urllib3\connectionpool.py", line 695, in urlopen
    **response_kw)
  File "c:\projects\next_bot\env\lib\site-packages\telegram\vendor\ptb_urllib3\urllib3\connectionpool.py", line 695, in urlopen
    **response_kw)
  File "c:\projects\next_bot\env\lib\site-packages\telegram\vendor\ptb_urllib3\urllib3\connectionpool.py", line 695, in urlopen
    **response_kw)
  File "c:\projects\next_bot\env\lib\site-packages\telegram\vendor\ptb_urllib3\urllib3\connectionpool.py", line 666, in urlopen
    _stacktrace=sys.exc_info()[2])
  File "c:\projects\next_bot\env\lib\site-packages\telegram\vendor\ptb_urllib3\urllib3\util\retry.py", line 376, in increment
    raise MaxRetryError(_pool, url, error or ResponseError(cause))
telegram.vendor.ptb_urllib3.urllib3.exceptions.MaxRetryError: HTTPSConnectionPool(host='api.telegram.org', port=443): Max retries exceeded with url: /bot822102958:AAHsgSxtLNp1FHMFXih30Rkpkx4DHFsvsFU/getUpdates (Caused by ConnectTimeoutError(<telegram.vendor.ptb_urllib3.urllib3.connection.VerifiedHTTPSConnection object at 0x0000012DE7C630F0>, 'Connection to api.telegram.org timed out. (connect timeout=5.0)'))

During handling of the above exception, another exception occurred:

Traceback (most recent call last):
  File "c:\projects\next_bot\env\lib\site-packages\telegram\ext\updater.py", line 332, in _network_loop_retry
    if not action_cb():
  File "c:\projects\next_bot\env\lib\site-packages\telegram\ext\updater.py", line 293, in polling_action_cb
    allowed_updates=allowed_updates)
  File "c:\projects\next_bot\env\lib\site-packages\telegram\bot.py", line 66, in decorator
    result = func(self, *args, **kwargs)
  File "c:\projects\next_bot\env\lib\site-packages\telegram\bot.py", line 1983, in get_updates
    result = self._request.post(url, data, timeout=float(read_latency) + float(timeout))
  File "c:\projects\next_bot\env\lib\site-packages\telegram\utils\request.py", line 327, in post
    **urlopen_kwargs)
  File "c:\projects\next_bot\env\lib\site-packages\telegram\utils\request.py", line 224, in _request_wrapper
    raise NetworkError('urllib3 HTTPError {0}'.format(error))
telegram.error.NetworkError: urllib3 HTTPError HTTPSConnectionPool(host='api.telegram.org', port=443): Max retries exceeded with url: /bot822102958:AAHsgSxtLNp1FHMFXih30Rkpkx4DHFsvsFU/getUpdates (Caused by ConnectTimeoutError(<telegram.vendor.ptb_urllib3.urllib3.connection.VerifiedHTTPSConnection object at 0x0000012DE7C630F0>, 'Connection to api.telegram.org timed out. (connect timeout=5.0)'))
2019-11-02 12:25:40,872 - WARNING - Retrying (Retry(total=2, connect=None, read=None, redirect=None)) after connection broken by 'ConnectTimeoutError(<telegram.vendor.ptb_urllib3.urllib3.connection.VerifiedHTTPSConnection object at 0x0000012DE7C63160>, 'Connection to api.telegram.org timed out. (connect timeout=5.0)')': /bot822102958:AAHsgSxtLNp1FHMFXih30Rkpkx4DHFsvsFU/getUpdates
2019-11-02 12:25:45,872 - WARNING - Retrying (Retry(total=1, connect=None, read=None, redirect=None)) after connection broken by 'ConnectTimeoutError(<telegram.vendor.ptb_urllib3.urllib3.connection.VerifiedHTTPSConnection object at 0x0000012DE7C63F60>, 'Connection to api.telegram.org timed out. (connect timeout=5.0)')': /bot822102958:AAHsgSxtLNp1FHMFXih30Rkpkx4DHFsvsFU/getUpdates
2019-11-02 12:25:50,873 - WARNING - Retrying (Retry(total=0, connect=None, read=None, redirect=None)) after connection broken by 'ConnectTimeoutError(<telegram.vendor.ptb_urllib3.urllib3.connection.VerifiedHTTPSConnection object at 0x0000012DE7C63F98>, 'Connection to api.telegram.org timed out. (connect timeout=5.0)')': /bot822102958:AAHsgSxtLNp1FHMFXih30Rkpkx4DHFsvsFU/getUpdates
2019-11-02 12:25:55,875 - ERROR - Error while getting Updates: urllib3 HTTPError HTTPSConnectionPool(host='api.telegram.org', port=443): Max retries exceeded with url: /bot822102958:AAHsgSxtLNp1FHMFXih30Rkpkx4DHFsvsFU/getUpdates (Caused by ConnectTimeoutError(<telegram.vendor.ptb_urllib3.urllib3.connection.VerifiedHTTPSConnection object at 0x0000012DE7C78198>, 'Connection to api.telegram.org timed out. (connect timeout=5.0)'))
2019-11-02 12:25:55,875 - ERROR - No error handlers are registered, logging exception.
Traceback (most recent call last):
  File "c:\projects\next_bot\env\lib\site-packages\telegram\vendor\ptb_urllib3\urllib3\connection.py", line 141, in _new_conn
    (self.host, self.port), self.timeout, **extra_kw)
  File "c:\projects\next_bot\env\lib\site-packages\telegram\vendor\ptb_urllib3\urllib3\util\connection.py", line 83, in create_connection
    raise err
  File "c:\projects\next_bot\env\lib\site-packages\telegram\vendor\ptb_urllib3\urllib3\util\connection.py", line 73, in create_connection
    sock.connect(sa)
socket.timeout: timed out

During handling of the above exception, another exception occurred:

Traceback (most recent call last):
  File "c:\projects\next_bot\env\lib\site-packages\telegram\vendor\ptb_urllib3\urllib3\connectionpool.py", line 617, in urlopen
    chunked=chunked)
  File "c:\projects\next_bot\env\lib\site-packages\telegram\vendor\ptb_urllib3\urllib3\connectionpool.py", line 360, in _make_request
    self._validate_conn(conn)
  File "c:\projects\next_bot\env\lib\site-packages\telegram\vendor\ptb_urllib3\urllib3\connectionpool.py", line 857, in _validate_conn
    super(HTTPSConnectionPool, self)._validate_conn(conn)
  File "c:\projects\next_bot\env\lib\site-packages\telegram\vendor\ptb_urllib3\urllib3\connectionpool.py", line 289, in _validate_conn
    conn.connect()
  File "c:\projects\next_bot\env\lib\site-packages\telegram\vendor\ptb_urllib3\urllib3\connection.py", line 284, in connect
    conn = self._new_conn()
  File "c:\projects\next_bot\env\lib\site-packages\telegram\vendor\ptb_urllib3\urllib3\connection.py", line 146, in _new_conn
    (self.host, self.timeout))
telegram.vendor.ptb_urllib3.urllib3.exceptions.ConnectTimeoutError: (<telegram.vendor.ptb_urllib3.urllib3.connection.VerifiedHTTPSConnection object at 0x0000012DE7C78198>, 'Connection to api.telegram.org timed out. (connect timeout=5.0)')

During handling of the above exception, another exception occurred:

Traceback (most recent call last):
  File "c:\projects\next_bot\env\lib\site-packages\telegram\utils\request.py", line 218, in _request_wrapper
    resp = self._con_pool.request(*args, **kwargs)
  File "c:\projects\next_bot\env\lib\site-packages\telegram\vendor\ptb_urllib3\urllib3\request.py", line 70, in request
    **urlopen_kw)
  File "c:\projects\next_bot\env\lib\site-packages\telegram\vendor\ptb_urllib3\urllib3\request.py", line 148, in request_encode_body
    return self.urlopen(method, url, **extra_kw)
  File "c:\projects\next_bot\env\lib\site-packages\telegram\vendor\ptb_urllib3\urllib3\poolmanager.py", line 244, in urlopen
    response = conn.urlopen(method, u.request_uri, **kw)
  File "c:\projects\next_bot\env\lib\site-packages\telegram\vendor\ptb_urllib3\urllib3\connectionpool.py", line 695, in urlopen
    **response_kw)
  File "c:\projects\next_bot\env\lib\site-packages\telegram\vendor\ptb_urllib3\urllib3\connectionpool.py", line 695, in urlopen
    **response_kw)
  File "c:\projects\next_bot\env\lib\site-packages\telegram\vendor\ptb_urllib3\urllib3\connectionpool.py", line 695, in urlopen
    **response_kw)
  File "c:\projects\next_bot\env\lib\site-packages\telegram\vendor\ptb_urllib3\urllib3\connectionpool.py", line 666, in urlopen
    _stacktrace=sys.exc_info()[2])
  File "c:\projects\next_bot\env\lib\site-packages\telegram\vendor\ptb_urllib3\urllib3\util\retry.py", line 376, in increment
    raise MaxRetryError(_pool, url, error or ResponseError(cause))
telegram.vendor.ptb_urllib3.urllib3.exceptions.MaxRetryError: HTTPSConnectionPool(host='api.telegram.org', port=443): Max retries exceeded with url: /bot822102958:AAHsgSxtLNp1FHMFXih30Rkpkx4DHFsvsFU/getUpdates (Caused by ConnectTimeoutError(<telegram.vendor.ptb_urllib3.urllib3.connection.VerifiedHTTPSConnection object at 0x0000012DE7C78198>, 'Connection to api.telegram.org timed out. (connect timeout=5.0)'))

During handling of the above exception, another exception occurred:

Traceback (most recent call last):
  File "c:\projects\next_bot\env\lib\site-packages\telegram\ext\updater.py", line 332, in _network_loop_retry
    if not action_cb():
  File "c:\projects\next_bot\env\lib\site-packages\telegram\ext\updater.py", line 293, in polling_action_cb
    allowed_updates=allowed_updates)
  File "c:\projects\next_bot\env\lib\site-packages\telegram\bot.py", line 66, in decorator
    result = func(self, *args, **kwargs)
  File "c:\projects\next_bot\env\lib\site-packages\telegram\bot.py", line 1983, in get_updates
    result = self._request.post(url, data, timeout=float(read_latency) + float(timeout))
  File "c:\projects\next_bot\env\lib\site-packages\telegram\utils\request.py", line 327, in post
    **urlopen_kwargs)
  File "c:\projects\next_bot\env\lib\site-packages\telegram\utils\request.py", line 224, in _request_wrapper
    raise NetworkError('urllib3 HTTPError {0}'.format(error))
telegram.error.NetworkError: urllib3 HTTPError HTTPSConnectionPool(host='api.telegram.org', port=443): Max retries exceeded with url: /bot822102958:AAHsgSxtLNp1FHMFXih30Rkpkx4DHFsvsFU/getUpdates (Caused by ConnectTimeoutError(<telegram.vendor.ptb_urllib3.urllib3.connection.VerifiedHTTPSConnection object at 0x0000012DE7C78198>, 'Connection to api.telegram.org timed out. (connect timeout=5.0)'))
2019-11-02 12:26:30,876 - WARNING - Retrying (Retry(total=2, connect=None, read=None, redirect=None)) after connection broken by 'ConnectTimeoutError(<telegram.vendor.ptb_urllib3.urllib3.connection.VerifiedHTTPSConnection object at 0x0000012DE7C783C8>, 'Connection to api.telegram.org timed out. (connect timeout=5.0)')': /bot822102958:AAHsgSxtLNp1FHMFXih30Rkpkx4DHFsvsFU/getUpdates
2019-11-02 12:26:35,877 - WARNING - Retrying (Retry(total=1, connect=None, read=None, redirect=None)) after connection broken by 'ConnectTimeoutError(<telegram.vendor.ptb_urllib3.urllib3.connection.VerifiedHTTPSConnection object at 0x0000012DE7C78550>, 'Connection to api.telegram.org timed out. (connect timeout=5.0)')': /bot822102958:AAHsgSxtLNp1FHMFXih30Rkpkx4DHFsvsFU/getUpdates
2019-11-02 12:26:40,879 - WARNING - Retrying (Retry(total=0, connect=None, read=None, redirect=None)) after connection broken by 'ConnectTimeoutError(<telegram.vendor.ptb_urllib3.urllib3.connection.VerifiedHTTPSConnection object at 0x0000012DE7C78630>, 'Connection to api.telegram.org timed out. (connect timeout=5.0)')': /bot822102958:AAHsgSxtLNp1FHMFXih30Rkpkx4DHFsvsFU/getUpdates
2019-11-02 12:26:45,880 - ERROR - Error while getting Updates: urllib3 HTTPError HTTPSConnectionPool(host='api.telegram.org', port=443): Max retries exceeded with url: /bot822102958:AAHsgSxtLNp1FHMFXih30Rkpkx4DHFsvsFU/getUpdates (Caused by ConnectTimeoutError(<telegram.vendor.ptb_urllib3.urllib3.connection.VerifiedHTTPSConnection object at 0x0000012DE7C78748>, 'Connection to api.telegram.org timed out. (connect timeout=5.0)'))
2019-11-02 12:26:45,880 - ERROR - No error handlers are registered, logging exception.
Traceback (most recent call last):
  File "c:\projects\next_bot\env\lib\site-packages\telegram\vendor\ptb_urllib3\urllib3\connection.py", line 141, in _new_conn
    (self.host, self.port), self.timeout, **extra_kw)
  File "c:\projects\next_bot\env\lib\site-packages\telegram\vendor\ptb_urllib3\urllib3\util\connection.py", line 83, in create_connection
    raise err
  File "c:\projects\next_bot\env\lib\site-packages\telegram\vendor\ptb_urllib3\urllib3\util\connection.py", line 73, in create_connection
    sock.connect(sa)
socket.timeout: timed out

During handling of the above exception, another exception occurred:

Traceback (most recent call last):
  File "c:\projects\next_bot\env\lib\site-packages\telegram\vendor\ptb_urllib3\urllib3\connectionpool.py", line 617, in urlopen
    chunked=chunked)
  File "c:\projects\next_bot\env\lib\site-packages\telegram\vendor\ptb_urllib3\urllib3\connectionpool.py", line 360, in _make_request
    self._validate_conn(conn)
  File "c:\projects\next_bot\env\lib\site-packages\telegram\vendor\ptb_urllib3\urllib3\connectionpool.py", line 857, in _validate_conn
    super(HTTPSConnectionPool, self)._validate_conn(conn)
  File "c:\projects\next_bot\env\lib\site-packages\telegram\vendor\ptb_urllib3\urllib3\connectionpool.py", line 289, in _validate_conn
    conn.connect()
  File "c:\projects\next_bot\env\lib\site-packages\telegram\vendor\ptb_urllib3\urllib3\connection.py", line 284, in connect
    conn = self._new_conn()
  File "c:\projects\next_bot\env\lib\site-packages\telegram\vendor\ptb_urllib3\urllib3\connection.py", line 146, in _new_conn
    (self.host, self.timeout))
telegram.vendor.ptb_urllib3.urllib3.exceptions.ConnectTimeoutError: (<telegram.vendor.ptb_urllib3.urllib3.connection.VerifiedHTTPSConnection object at 0x0000012DE7C78748>, 'Connection to api.telegram.org timed out. (connect timeout=5.0)')

During handling of the above exception, another exception occurred:

Traceback (most recent call last):
  File "c:\projects\next_bot\env\lib\site-packages\telegram\utils\request.py", line 218, in _request_wrapper
    resp = self._con_pool.request(*args, **kwargs)
  File "c:\projects\next_bot\env\lib\site-packages\telegram\vendor\ptb_urllib3\urllib3\request.py", line 70, in request
    **urlopen_kw)
  File "c:\projects\next_bot\env\lib\site-packages\telegram\vendor\ptb_urllib3\urllib3\request.py", line 148, in request_encode_body
    return self.urlopen(method, url, **extra_kw)
  File "c:\projects\next_bot\env\lib\site-packages\telegram\vendor\ptb_urllib3\urllib3\poolmanager.py", line 244, in urlopen
    response = conn.urlopen(method, u.request_uri, **kw)
  File "c:\projects\next_bot\env\lib\site-packages\telegram\vendor\ptb_urllib3\urllib3\connectionpool.py", line 695, in urlopen
    **response_kw)
  File "c:\projects\next_bot\env\lib\site-packages\telegram\vendor\ptb_urllib3\urllib3\connectionpool.py", line 695, in urlopen
    **response_kw)
  File "c:\projects\next_bot\env\lib\site-packages\telegram\vendor\ptb_urllib3\urllib3\connectionpool.py", line 695, in urlopen
    **response_kw)
  File "c:\projects\next_bot\env\lib\site-packages\telegram\vendor\ptb_urllib3\urllib3\connectionpool.py", line 666, in urlopen
    _stacktrace=sys.exc_info()[2])
  File "c:\projects\next_bot\env\lib\site-packages\telegram\vendor\ptb_urllib3\urllib3\util\retry.py", line 376, in increment
    raise MaxRetryError(_pool, url, error or ResponseError(cause))
telegram.vendor.ptb_urllib3.urllib3.exceptions.MaxRetryError: HTTPSConnectionPool(host='api.telegram.org', port=443): Max retries exceeded with url: /bot822102958:AAHsgSxtLNp1FHMFXih30Rkpkx4DHFsvsFU/getUpdates (Caused by ConnectTimeoutError(<telegram.vendor.ptb_urllib3.urllib3.connection.VerifiedHTTPSConnection object at 0x0000012DE7C78748>, 'Connection to api.telegram.org timed out. (connect timeout=5.0)'))

During handling of the above exception, another exception occurred:

Traceback (most recent call last):
  File "c:\projects\next_bot\env\lib\site-packages\telegram\ext\updater.py", line 332, in _network_loop_retry
    if not action_cb():
  File "c:\projects\next_bot\env\lib\site-packages\telegram\ext\updater.py", line 293, in polling_action_cb
    allowed_updates=allowed_updates)
  File "c:\projects\next_bot\env\lib\site-packages\telegram\bot.py", line 66, in decorator
    result = func(self, *args, **kwargs)
  File "c:\projects\next_bot\env\lib\site-packages\telegram\bot.py", line 1983, in get_updates
    result = self._request.post(url, data, timeout=float(read_latency) + float(timeout))
  File "c:\projects\next_bot\env\lib\site-packages\telegram\utils\request.py", line 327, in post
    **urlopen_kwargs)
  File "c:\projects\next_bot\env\lib\site-packages\telegram\utils\request.py", line 224, in _request_wrapper
    raise NetworkError('urllib3 HTTPError {0}'.format(error))
telegram.error.NetworkError: urllib3 HTTPError HTTPSConnectionPool(host='api.telegram.org', port=443): Max retries exceeded with url: /bot822102958:AAHsgSxtLNp1FHMFXih30Rkpkx4DHFsvsFU/getUpdates (Caused by ConnectTimeoutError(<telegram.vendor.ptb_urllib3.urllib3.connection.VerifiedHTTPSConnection object at 0x0000012DE7C78748>, 'Connection to api.telegram.org timed out. (connect timeout=5.0)'))
2019-11-02 12:27:20,883 - WARNING - Retrying (Retry(total=2, connect=None, read=None, redirect=None)) after connection broken by 'ConnectTimeoutError(<telegram.vendor.ptb_urllib3.urllib3.connection.VerifiedHTTPSConnection object at 0x0000012DE7C782E8>, 'Connection to api.telegram.org timed out. (connect timeout=5.0)')': /bot822102958:AAHsgSxtLNp1FHMFXih30Rkpkx4DHFsvsFU/getUpdates
2019-11-02 12:27:25,884 - WARNING - Retrying (Retry(total=1, connect=None, read=None, redirect=None)) after connection broken by 'ConnectTimeoutError(<telegram.vendor.ptb_urllib3.urllib3.connection.VerifiedHTTPSConnection object at 0x0000012DE7C78B00>, 'Connection to api.telegram.org timed out. (connect timeout=5.0)')': /bot822102958:AAHsgSxtLNp1FHMFXih30Rkpkx4DHFsvsFU/getUpdates
2019-11-02 12:27:30,886 - WARNING - Retrying (Retry(total=0, connect=None, read=None, redirect=None)) after connection broken by 'ConnectTimeoutError(<telegram.vendor.ptb_urllib3.urllib3.connection.VerifiedHTTPSConnection object at 0x0000012DE7C78BE0>, 'Connection to api.telegram.org timed out. (connect timeout=5.0)')': /bot822102958:AAHsgSxtLNp1FHMFXih30Rkpkx4DHFsvsFU/getUpdates
2019-11-02 12:27:35,887 - ERROR - Error while getting Updates: urllib3 HTTPError HTTPSConnectionPool(host='api.telegram.org', port=443): Max retries exceeded with url: /bot822102958:AAHsgSxtLNp1FHMFXih30Rkpkx4DHFsvsFU/getUpdates (Caused by ConnectTimeoutError(<telegram.vendor.ptb_urllib3.urllib3.connection.VerifiedHTTPSConnection object at 0x0000012DE7C48C50>, 'Connection to api.telegram.org timed out. (connect timeout=5.0)'))
2019-11-02 12:27:35,887 - ERROR - No error handlers are registered, logging exception.
Traceback (most recent call last):
  File "c:\projects\next_bot\env\lib\site-packages\telegram\vendor\ptb_urllib3\urllib3\connection.py", line 141, in _new_conn
    (self.host, self.port), self.timeout, **extra_kw)
  File "c:\projects\next_bot\env\lib\site-packages\telegram\vendor\ptb_urllib3\urllib3\util\connection.py", line 83, in create_connection
    raise err
  File "c:\projects\next_bot\env\lib\site-packages\telegram\vendor\ptb_urllib3\urllib3\util\connection.py", line 73, in create_connection
    sock.connect(sa)
socket.timeout: timed out

During handling of the above exception, another exception occurred:

Traceback (most recent call last):
  File "c:\projects\next_bot\env\lib\site-packages\telegram\vendor\ptb_urllib3\urllib3\connectionpool.py", line 617, in urlopen
    chunked=chunked)
  File "c:\projects\next_bot\env\lib\site-packages\telegram\vendor\ptb_urllib3\urllib3\connectionpool.py", line 360, in _make_request
    self._validate_conn(conn)
  File "c:\projects\next_bot\env\lib\site-packages\telegram\vendor\ptb_urllib3\urllib3\connectionpool.py", line 857, in _validate_conn
    super(HTTPSConnectionPool, self)._validate_conn(conn)
  File "c:\projects\next_bot\env\lib\site-packages\telegram\vendor\ptb_urllib3\urllib3\connectionpool.py", line 289, in _validate_conn
    conn.connect()
  File "c:\projects\next_bot\env\lib\site-packages\telegram\vendor\ptb_urllib3\urllib3\connection.py", line 284, in connect
    conn = self._new_conn()
  File "c:\projects\next_bot\env\lib\site-packages\telegram\vendor\ptb_urllib3\urllib3\connection.py", line 146, in _new_conn
    (self.host, self.timeout))
telegram.vendor.ptb_urllib3.urllib3.exceptions.ConnectTimeoutError: (<telegram.vendor.ptb_urllib3.urllib3.connection.VerifiedHTTPSConnection object at 0x0000012DE7C48C50>, 'Connection to api.telegram.org timed out. (connect timeout=5.0)')

During handling of the above exception, another exception occurred:

Traceback (most recent call last):
  File "c:\projects\next_bot\env\lib\site-packages\telegram\utils\request.py", line 218, in _request_wrapper
    resp = self._con_pool.request(*args, **kwargs)
  File "c:\projects\next_bot\env\lib\site-packages\telegram\vendor\ptb_urllib3\urllib3\request.py", line 70, in request
    **urlopen_kw)
  File "c:\projects\next_bot\env\lib\site-packages\telegram\vendor\ptb_urllib3\urllib3\request.py", line 148, in request_encode_body
    return self.urlopen(method, url, **extra_kw)
  File "c:\projects\next_bot\env\lib\site-packages\telegram\vendor\ptb_urllib3\urllib3\poolmanager.py", line 244, in urlopen
    response = conn.urlopen(method, u.request_uri, **kw)
  File "c:\projects\next_bot\env\lib\site-packages\telegram\vendor\ptb_urllib3\urllib3\connectionpool.py", line 695, in urlopen
    **response_kw)
  File "c:\projects\next_bot\env\lib\site-packages\telegram\vendor\ptb_urllib3\urllib3\connectionpool.py", line 695, in urlopen
    **response_kw)
  File "c:\projects\next_bot\env\lib\site-packages\telegram\vendor\ptb_urllib3\urllib3\connectionpool.py", line 695, in urlopen
    **response_kw)
  File "c:\projects\next_bot\env\lib\site-packages\telegram\vendor\ptb_urllib3\urllib3\connectionpool.py", line 666, in urlopen
    _stacktrace=sys.exc_info()[2])
  File "c:\projects\next_bot\env\lib\site-packages\telegram\vendor\ptb_urllib3\urllib3\util\retry.py", line 376, in increment
    raise MaxRetryError(_pool, url, error or ResponseError(cause))
telegram.vendor.ptb_urllib3.urllib3.exceptions.MaxRetryError: HTTPSConnectionPool(host='api.telegram.org', port=443): Max retries exceeded with url: /bot822102958:AAHsgSxtLNp1FHMFXih30Rkpkx4DHFsvsFU/getUpdates (Caused by ConnectTimeoutError(<telegram.vendor.ptb_urllib3.urllib3.connection.VerifiedHTTPSConnection object at 0x0000012DE7C48C50>, 'Connection to api.telegram.org timed out. (connect timeout=5.0)'))

During handling of the above exception, another exception occurred:

Traceback (most recent call last):
  File "c:\projects\next_bot\env\lib\site-packages\telegram\ext\updater.py", line 332, in _network_loop_retry
    if not action_cb():
  File "c:\projects\next_bot\env\lib\site-packages\telegram\ext\updater.py", line 293, in polling_action_cb
    allowed_updates=allowed_updates)
  File "c:\projects\next_bot\env\lib\site-packages\telegram\bot.py", line 66, in decorator
    result = func(self, *args, **kwargs)
  File "c:\projects\next_bot\env\lib\site-packages\telegram\bot.py", line 1983, in get_updates
    result = self._request.post(url, data, timeout=float(read_latency) + float(timeout))
  File "c:\projects\next_bot\env\lib\site-packages\telegram\utils\request.py", line 327, in post
    **urlopen_kwargs)
  File "c:\projects\next_bot\env\lib\site-packages\telegram\utils\request.py", line 224, in _request_wrapper
    raise NetworkError('urllib3 HTTPError {0}'.format(error))
telegram.error.NetworkError: urllib3 HTTPError HTTPSConnectionPool(host='api.telegram.org', port=443): Max retries exceeded with url: /bot822102958:AAHsgSxtLNp1FHMFXih30Rkpkx4DHFsvsFU/getUpdates (Caused by ConnectTimeoutError(<telegram.vendor.ptb_urllib3.urllib3.connection.VerifiedHTTPSConnection object at 0x0000012DE7C48C50>, 'Connection to api.telegram.org timed out. (connect timeout=5.0)'))
2019-11-02 12:28:10,888 - WARNING - Retrying (Retry(total=2, connect=None, read=None, redirect=None)) after connection broken by 'ConnectTimeoutError(<telegram.vendor.ptb_urllib3.urllib3.connection.VerifiedHTTPSConnection object at 0x0000012DE7C48B70>, 'Connection to api.telegram.org timed out. (connect timeout=5.0)')': /bot822102958:AAHsgSxtLNp1FHMFXih30Rkpkx4DHFsvsFU/getUpdates
2019-11-02 12:28:15,890 - WARNING - Retrying (Retry(total=1, connect=None, read=None, redirect=None)) after connection broken by 'ConnectTimeoutError(<telegram.vendor.ptb_urllib3.urllib3.connection.VerifiedHTTPSConnection object at 0x0000012DE7C48F28>, 'Connection to api.telegram.org timed out. (connect timeout=5.0)')': /bot822102958:AAHsgSxtLNp1FHMFXih30Rkpkx4DHFsvsFU/getUpdates
2019-11-02 12:28:20,891 - WARNING - Retrying (Retry(total=0, connect=None, read=None, redirect=None)) after connection broken by 'ConnectTimeoutError(<telegram.vendor.ptb_urllib3.urllib3.connection.VerifiedHTTPSConnection object at 0x0000012DE7C48780>, 'Connection to api.telegram.org timed out. (connect timeout=5.0)')': /bot822102958:AAHsgSxtLNp1FHMFXih30Rkpkx4DHFsvsFU/getUpdates
2019-11-02 12:28:25,892 - ERROR - Error while getting Updates: urllib3 HTTPError HTTPSConnectionPool(host='api.telegram.org', port=443): Max retries exceeded with url: /bot822102958:AAHsgSxtLNp1FHMFXih30Rkpkx4DHFsvsFU/getUpdates (Caused by ConnectTimeoutError(<telegram.vendor.ptb_urllib3.urllib3.connection.VerifiedHTTPSConnection object at 0x0000012DE7C48080>, 'Connection to api.telegram.org timed out. (connect timeout=5.0)'))
2019-11-02 12:28:25,892 - ERROR - No error handlers are registered, logging exception.
Traceback (most recent call last):
  File "c:\projects\next_bot\env\lib\site-packages\telegram\vendor\ptb_urllib3\urllib3\connection.py", line 141, in _new_conn
    (self.host, self.port), self.timeout, **extra_kw)
  File "c:\projects\next_bot\env\lib\site-packages\telegram\vendor\ptb_urllib3\urllib3\util\connection.py", line 83, in create_connection
    raise err
  File "c:\projects\next_bot\env\lib\site-packages\telegram\vendor\ptb_urllib3\urllib3\util\connection.py", line 73, in create_connection
    sock.connect(sa)
socket.timeout: timed out

During handling of the above exception, another exception occurred:

Traceback (most recent call last):
  File "c:\projects\next_bot\env\lib\site-packages\telegram\vendor\ptb_urllib3\urllib3\connectionpool.py", line 617, in urlopen
    chunked=chunked)
  File "c:\projects\next_bot\env\lib\site-packages\telegram\vendor\ptb_urllib3\urllib3\connectionpool.py", line 360, in _make_request
    self._validate_conn(conn)
  File "c:\projects\next_bot\env\lib\site-packages\telegram\vendor\ptb_urllib3\urllib3\connectionpool.py", line 857, in _validate_conn
    super(HTTPSConnectionPool, self)._validate_conn(conn)
  File "c:\projects\next_bot\env\lib\site-packages\telegram\vendor\ptb_urllib3\urllib3\connectionpool.py", line 289, in _validate_conn
    conn.connect()
  File "c:\projects\next_bot\env\lib\site-packages\telegram\vendor\ptb_urllib3\urllib3\connection.py", line 284, in connect
    conn = self._new_conn()
  File "c:\projects\next_bot\env\lib\site-packages\telegram\vendor\ptb_urllib3\urllib3\connection.py", line 146, in _new_conn
    (self.host, self.timeout))
telegram.vendor.ptb_urllib3.urllib3.exceptions.ConnectTimeoutError: (<telegram.vendor.ptb_urllib3.urllib3.connection.VerifiedHTTPSConnection object at 0x0000012DE7C48080>, 'Connection to api.telegram.org timed out. (connect timeout=5.0)')

During handling of the above exception, another exception occurred:

Traceback (most recent call last):
  File "c:\projects\next_bot\env\lib\site-packages\telegram\utils\request.py", line 218, in _request_wrapper
    resp = self._con_pool.request(*args, **kwargs)
  File "c:\projects\next_bot\env\lib\site-packages\telegram\vendor\ptb_urllib3\urllib3\request.py", line 70, in request
    **urlopen_kw)
  File "c:\projects\next_bot\env\lib\site-packages\telegram\vendor\ptb_urllib3\urllib3\request.py", line 148, in request_encode_body
    return self.urlopen(method, url, **extra_kw)
  File "c:\projects\next_bot\env\lib\site-packages\telegram\vendor\ptb_urllib3\urllib3\poolmanager.py", line 244, in urlopen
    response = conn.urlopen(method, u.request_uri, **kw)
  File "c:\projects\next_bot\env\lib\site-packages\telegram\vendor\ptb_urllib3\urllib3\connectionpool.py", line 695, in urlopen
    **response_kw)
  File "c:\projects\next_bot\env\lib\site-packages\telegram\vendor\ptb_urllib3\urllib3\connectionpool.py", line 695, in urlopen
    **response_kw)
  File "c:\projects\next_bot\env\lib\site-packages\telegram\vendor\ptb_urllib3\urllib3\connectionpool.py", line 695, in urlopen
    **response_kw)
  File "c:\projects\next_bot\env\lib\site-packages\telegram\vendor\ptb_urllib3\urllib3\connectionpool.py", line 666, in urlopen
    _stacktrace=sys.exc_info()[2])
  File "c:\projects\next_bot\env\lib\site-packages\telegram\vendor\ptb_urllib3\urllib3\util\retry.py", line 376, in increment
    raise MaxRetryError(_pool, url, error or ResponseError(cause))
telegram.vendor.ptb_urllib3.urllib3.exceptions.MaxRetryError: HTTPSConnectionPool(host='api.telegram.org', port=443): Max retries exceeded with url: /bot822102958:AAHsgSxtLNp1FHMFXih30Rkpkx4DHFsvsFU/getUpdates (Caused by ConnectTimeoutError(<telegram.vendor.ptb_urllib3.urllib3.connection.VerifiedHTTPSConnection object at 0x0000012DE7C48080>, 'Connection to api.telegram.org timed out. (connect timeout=5.0)'))

During handling of the above exception, another exception occurred:

Traceback (most recent call last):
  File "c:\projects\next_bot\env\lib\site-packages\telegram\ext\updater.py", line 332, in _network_loop_retry
    if not action_cb():
  File "c:\projects\next_bot\env\lib\site-packages\telegram\ext\updater.py", line 293, in polling_action_cb
    allowed_updates=allowed_updates)
  File "c:\projects\next_bot\env\lib\site-packages\telegram\bot.py", line 66, in decorator
    result = func(self, *args, **kwargs)
  File "c:\projects\next_bot\env\lib\site-packages\telegram\bot.py", line 1983, in get_updates
    result = self._request.post(url, data, timeout=float(read_latency) + float(timeout))
  File "c:\projects\next_bot\env\lib\site-packages\telegram\utils\request.py", line 327, in post
    **urlopen_kwargs)
  File "c:\projects\next_bot\env\lib\site-packages\telegram\utils\request.py", line 224, in _request_wrapper
    raise NetworkError('urllib3 HTTPError {0}'.format(error))
telegram.error.NetworkError: urllib3 HTTPError HTTPSConnectionPool(host='api.telegram.org', port=443): Max retries exceeded with url: /bot822102958:AAHsgSxtLNp1FHMFXih30Rkpkx4DHFsvsFU/getUpdates (Caused by ConnectTimeoutError(<telegram.vendor.ptb_urllib3.urllib3.connection.VerifiedHTTPSConnection object at 0x0000012DE7C48080>, 'Connection to api.telegram.org timed out. (connect timeout=5.0)'))
2019-11-02 12:29:00,905 - WARNING - Retrying (Retry(total=2, connect=None, read=None, redirect=None)) after connection broken by 'ConnectTimeoutError(<telegram.vendor.ptb_urllib3.urllib3.connection.VerifiedHTTPSConnection object at 0x0000012DE7C48048>, 'Connection to api.telegram.org timed out. (connect timeout=5.0)')': /bot822102958:AAHsgSxtLNp1FHMFXih30Rkpkx4DHFsvsFU/getUpdates
2019-11-02 12:29:05,905 - WARNING - Retrying (Retry(total=1, connect=None, read=None, redirect=None)) after connection broken by 'ConnectTimeoutError(<telegram.vendor.ptb_urllib3.urllib3.connection.VerifiedHTTPSConnection object at 0x0000012DE735FFD0>, 'Connection to api.telegram.org timed out. (connect timeout=5.0)')': /bot822102958:AAHsgSxtLNp1FHMFXih30Rkpkx4DHFsvsFU/getUpdates
2019-11-02 12:29:10,907 - WARNING - Retrying (Retry(total=0, connect=None, read=None, redirect=None)) after connection broken by 'ConnectTimeoutError(<telegram.vendor.ptb_urllib3.urllib3.connection.VerifiedHTTPSConnection object at 0x0000012DE7331F60>, 'Connection to api.telegram.org timed out. (connect timeout=5.0)')': /bot822102958:AAHsgSxtLNp1FHMFXih30Rkpkx4DHFsvsFU/getUpdates
2019-11-02 12:29:15,909 - ERROR - Error while getting Updates: urllib3 HTTPError HTTPSConnectionPool(host='api.telegram.org', port=443): Max retries exceeded with url: /bot822102958:AAHsgSxtLNp1FHMFXih30Rkpkx4DHFsvsFU/getUpdates (Caused by ConnectTimeoutError(<telegram.vendor.ptb_urllib3.urllib3.connection.VerifiedHTTPSConnection object at 0x0000012DE7331780>, 'Connection to api.telegram.org timed out. (connect timeout=5.0)'))
2019-11-02 12:29:15,909 - ERROR - No error handlers are registered, logging exception.
Traceback (most recent call last):
  File "c:\projects\next_bot\env\lib\site-packages\telegram\vendor\ptb_urllib3\urllib3\connection.py", line 141, in _new_conn
    (self.host, self.port), self.timeout, **extra_kw)
  File "c:\projects\next_bot\env\lib\site-packages\telegram\vendor\ptb_urllib3\urllib3\util\connection.py", line 83, in create_connection
    raise err
  File "c:\projects\next_bot\env\lib\site-packages\telegram\vendor\ptb_urllib3\urllib3\util\connection.py", line 73, in create_connection
    sock.connect(sa)
socket.timeout: timed out

During handling of the above exception, another exception occurred:

Traceback (most recent call last):
  File "c:\projects\next_bot\env\lib\site-packages\telegram\vendor\ptb_urllib3\urllib3\connectionpool.py", line 617, in urlopen
    chunked=chunked)
  File "c:\projects\next_bot\env\lib\site-packages\telegram\vendor\ptb_urllib3\urllib3\connectionpool.py", line 360, in _make_request
    self._validate_conn(conn)
  File "c:\projects\next_bot\env\lib\site-packages\telegram\vendor\ptb_urllib3\urllib3\connectionpool.py", line 857, in _validate_conn
    super(HTTPSConnectionPool, self)._validate_conn(conn)
  File "c:\projects\next_bot\env\lib\site-packages\telegram\vendor\ptb_urllib3\urllib3\connectionpool.py", line 289, in _validate_conn
    conn.connect()
  File "c:\projects\next_bot\env\lib\site-packages\telegram\vendor\ptb_urllib3\urllib3\connection.py", line 284, in connect
    conn = self._new_conn()
  File "c:\projects\next_bot\env\lib\site-packages\telegram\vendor\ptb_urllib3\urllib3\connection.py", line 146, in _new_conn
    (self.host, self.timeout))
telegram.vendor.ptb_urllib3.urllib3.exceptions.ConnectTimeoutError: (<telegram.vendor.ptb_urllib3.urllib3.connection.VerifiedHTTPSConnection object at 0x0000012DE7331780>, 'Connection to api.telegram.org timed out. (connect timeout=5.0)')

During handling of the above exception, another exception occurred:

Traceback (most recent call last):
  File "c:\projects\next_bot\env\lib\site-packages\telegram\utils\request.py", line 218, in _request_wrapper
    resp = self._con_pool.request(*args, **kwargs)
  File "c:\projects\next_bot\env\lib\site-packages\telegram\vendor\ptb_urllib3\urllib3\request.py", line 70, in request
    **urlopen_kw)
  File "c:\projects\next_bot\env\lib\site-packages\telegram\vendor\ptb_urllib3\urllib3\request.py", line 148, in request_encode_body
    return self.urlopen(method, url, **extra_kw)
  File "c:\projects\next_bot\env\lib\site-packages\telegram\vendor\ptb_urllib3\urllib3\poolmanager.py", line 244, in urlopen
    response = conn.urlopen(method, u.request_uri, **kw)
  File "c:\projects\next_bot\env\lib\site-packages\telegram\vendor\ptb_urllib3\urllib3\connectionpool.py", line 695, in urlopen
    **response_kw)
  File "c:\projects\next_bot\env\lib\site-packages\telegram\vendor\ptb_urllib3\urllib3\connectionpool.py", line 695, in urlopen
    **response_kw)
  File "c:\projects\next_bot\env\lib\site-packages\telegram\vendor\ptb_urllib3\urllib3\connectionpool.py", line 695, in urlopen
    **response_kw)
  File "c:\projects\next_bot\env\lib\site-packages\telegram\vendor\ptb_urllib3\urllib3\connectionpool.py", line 666, in urlopen
    _stacktrace=sys.exc_info()[2])
  File "c:\projects\next_bot\env\lib\site-packages\telegram\vendor\ptb_urllib3\urllib3\util\retry.py", line 376, in increment
    raise MaxRetryError(_pool, url, error or ResponseError(cause))
telegram.vendor.ptb_urllib3.urllib3.exceptions.MaxRetryError: HTTPSConnectionPool(host='api.telegram.org', port=443): Max retries exceeded with url: /bot822102958:AAHsgSxtLNp1FHMFXih30Rkpkx4DHFsvsFU/getUpdates (Caused by ConnectTimeoutError(<telegram.vendor.ptb_urllib3.urllib3.connection.VerifiedHTTPSConnection object at 0x0000012DE7331780>, 'Connection to api.telegram.org timed out. (connect timeout=5.0)'))

During handling of the above exception, another exception occurred:

Traceback (most recent call last):
  File "c:\projects\next_bot\env\lib\site-packages\telegram\ext\updater.py", line 332, in _network_loop_retry
    if not action_cb():
  File "c:\projects\next_bot\env\lib\site-packages\telegram\ext\updater.py", line 293, in polling_action_cb
    allowed_updates=allowed_updates)
  File "c:\projects\next_bot\env\lib\site-packages\telegram\bot.py", line 66, in decorator
    result = func(self, *args, **kwargs)
  File "c:\projects\next_bot\env\lib\site-packages\telegram\bot.py", line 1983, in get_updates
    result = self._request.post(url, data, timeout=float(read_latency) + float(timeout))
  File "c:\projects\next_bot\env\lib\site-packages\telegram\utils\request.py", line 327, in post
    **urlopen_kwargs)
  File "c:\projects\next_bot\env\lib\site-packages\telegram\utils\request.py", line 224, in _request_wrapper
    raise NetworkError('urllib3 HTTPError {0}'.format(error))
telegram.error.NetworkError: urllib3 HTTPError HTTPSConnectionPool(host='api.telegram.org', port=443): Max retries exceeded with url: /bot822102958:AAHsgSxtLNp1FHMFXih30Rkpkx4DHFsvsFU/getUpdates (Caused by ConnectTimeoutError(<telegram.vendor.ptb_urllib3.urllib3.connection.VerifiedHTTPSConnection object at 0x0000012DE7331780>, 'Connection to api.telegram.org timed out. (connect timeout=5.0)'))
2019-11-02 12:29:50,911 - WARNING - Retrying (Retry(total=2, connect=None, read=None, redirect=None)) after connection broken by 'ConnectTimeoutError(<telegram.vendor.ptb_urllib3.urllib3.connection.VerifiedHTTPSConnection object at 0x0000012DE7331E10>, 'Connection to api.telegram.org timed out. (connect timeout=5.0)')': /bot822102958:AAHsgSxtLNp1FHMFXih30Rkpkx4DHFsvsFU/getUpdates
2019-11-02 12:29:55,912 - WARNING - Retrying (Retry(total=1, connect=None, read=None, redirect=None)) after connection broken by 'ConnectTimeoutError(<telegram.vendor.ptb_urllib3.urllib3.connection.VerifiedHTTPSConnection object at 0x0000012DE7331CF8>, 'Connection to api.telegram.org timed out. (connect timeout=5.0)')': /bot822102958:AAHsgSxtLNp1FHMFXih30Rkpkx4DHFsvsFU/getUpdates
2019-11-02 12:30:00,913 - WARNING - Retrying (Retry(total=0, connect=None, read=None, redirect=None)) after connection broken by 'ConnectTimeoutError(<telegram.vendor.ptb_urllib3.urllib3.connection.VerifiedHTTPSConnection object at 0x0000012DE7C63EB8>, 'Connection to api.telegram.org timed out. (connect timeout=5.0)')': /bot822102958:AAHsgSxtLNp1FHMFXih30Rkpkx4DHFsvsFU/getUpdates
2019-11-02 12:30:05,914 - ERROR - Error while getting Updates: urllib3 HTTPError HTTPSConnectionPool(host='api.telegram.org', port=443): Max retries exceeded with url: /bot822102958:AAHsgSxtLNp1FHMFXih30Rkpkx4DHFsvsFU/getUpdates (Caused by ConnectTimeoutError(<telegram.vendor.ptb_urllib3.urllib3.connection.VerifiedHTTPSConnection object at 0x0000012DE7C63F98>, 'Connection to api.telegram.org timed out. (connect timeout=5.0)'))
2019-11-02 12:30:05,914 - ERROR - No error handlers are registered, logging exception.
Traceback (most recent call last):
  File "c:\projects\next_bot\env\lib\site-packages\telegram\vendor\ptb_urllib3\urllib3\connection.py", line 141, in _new_conn
    (self.host, self.port), self.timeout, **extra_kw)
  File "c:\projects\next_bot\env\lib\site-packages\telegram\vendor\ptb_urllib3\urllib3\util\connection.py", line 83, in create_connection
    raise err
  File "c:\projects\next_bot\env\lib\site-packages\telegram\vendor\ptb_urllib3\urllib3\util\connection.py", line 73, in create_connection
    sock.connect(sa)
socket.timeout: timed out

During handling of the above exception, another exception occurred:

Traceback (most recent call last):
  File "c:\projects\next_bot\env\lib\site-packages\telegram\vendor\ptb_urllib3\urllib3\connectionpool.py", line 617, in urlopen
    chunked=chunked)
  File "c:\projects\next_bot\env\lib\site-packages\telegram\vendor\ptb_urllib3\urllib3\connectionpool.py", line 360, in _make_request
    self._validate_conn(conn)
  File "c:\projects\next_bot\env\lib\site-packages\telegram\vendor\ptb_urllib3\urllib3\connectionpool.py", line 857, in _validate_conn
    super(HTTPSConnectionPool, self)._validate_conn(conn)
  File "c:\projects\next_bot\env\lib\site-packages\telegram\vendor\ptb_urllib3\urllib3\connectionpool.py", line 289, in _validate_conn
    conn.connect()
  File "c:\projects\next_bot\env\lib\site-packages\telegram\vendor\ptb_urllib3\urllib3\connection.py", line 284, in connect
    conn = self._new_conn()
  File "c:\projects\next_bot\env\lib\site-packages\telegram\vendor\ptb_urllib3\urllib3\connection.py", line 146, in _new_conn
    (self.host, self.timeout))
telegram.vendor.ptb_urllib3.urllib3.exceptions.ConnectTimeoutError: (<telegram.vendor.ptb_urllib3.urllib3.connection.VerifiedHTTPSConnection object at 0x0000012DE7C63F98>, 'Connection to api.telegram.org timed out. (connect timeout=5.0)')

During handling of the above exception, another exception occurred:

Traceback (most recent call last):
  File "c:\projects\next_bot\env\lib\site-packages\telegram\utils\request.py", line 218, in _request_wrapper
    resp = self._con_pool.request(*args, **kwargs)
  File "c:\projects\next_bot\env\lib\site-packages\telegram\vendor\ptb_urllib3\urllib3\request.py", line 70, in request
    **urlopen_kw)
  File "c:\projects\next_bot\env\lib\site-packages\telegram\vendor\ptb_urllib3\urllib3\request.py", line 148, in request_encode_body
    return self.urlopen(method, url, **extra_kw)
  File "c:\projects\next_bot\env\lib\site-packages\telegram\vendor\ptb_urllib3\urllib3\poolmanager.py", line 244, in urlopen
    response = conn.urlopen(method, u.request_uri, **kw)
  File "c:\projects\next_bot\env\lib\site-packages\telegram\vendor\ptb_urllib3\urllib3\connectionpool.py", line 695, in urlopen
    **response_kw)
  File "c:\projects\next_bot\env\lib\site-packages\telegram\vendor\ptb_urllib3\urllib3\connectionpool.py", line 695, in urlopen
    **response_kw)
  File "c:\projects\next_bot\env\lib\site-packages\telegram\vendor\ptb_urllib3\urllib3\connectionpool.py", line 695, in urlopen
    **response_kw)
  File "c:\projects\next_bot\env\lib\site-packages\telegram\vendor\ptb_urllib3\urllib3\connectionpool.py", line 666, in urlopen
    _stacktrace=sys.exc_info()[2])
  File "c:\projects\next_bot\env\lib\site-packages\telegram\vendor\ptb_urllib3\urllib3\util\retry.py", line 376, in increment
    raise MaxRetryError(_pool, url, error or ResponseError(cause))
telegram.vendor.ptb_urllib3.urllib3.exceptions.MaxRetryError: HTTPSConnectionPool(host='api.telegram.org', port=443): Max retries exceeded with url: /bot822102958:AAHsgSxtLNp1FHMFXih30Rkpkx4DHFsvsFU/getUpdates (Caused by ConnectTimeoutError(<telegram.vendor.ptb_urllib3.urllib3.connection.VerifiedHTTPSConnection object at 0x0000012DE7C63F98>, 'Connection to api.telegram.org timed out. (connect timeout=5.0)'))

During handling of the above exception, another exception occurred:

Traceback (most recent call last):
  File "c:\projects\next_bot\env\lib\site-packages\telegram\ext\updater.py", line 332, in _network_loop_retry
    if not action_cb():
  File "c:\projects\next_bot\env\lib\site-packages\telegram\ext\updater.py", line 293, in polling_action_cb
    allowed_updates=allowed_updates)
  File "c:\projects\next_bot\env\lib\site-packages\telegram\bot.py", line 66, in decorator
    result = func(self, *args, **kwargs)
  File "c:\projects\next_bot\env\lib\site-packages\telegram\bot.py", line 1983, in get_updates
    result = self._request.post(url, data, timeout=float(read_latency) + float(timeout))
  File "c:\projects\next_bot\env\lib\site-packages\telegram\utils\request.py", line 327, in post
    **urlopen_kwargs)
  File "c:\projects\next_bot\env\lib\site-packages\telegram\utils\request.py", line 224, in _request_wrapper
    raise NetworkError('urllib3 HTTPError {0}'.format(error))
telegram.error.NetworkError: urllib3 HTTPError HTTPSConnectionPool(host='api.telegram.org', port=443): Max retries exceeded with url: /bot822102958:AAHsgSxtLNp1FHMFXih30Rkpkx4DHFsvsFU/getUpdates (Caused by ConnectTimeoutError(<telegram.vendor.ptb_urllib3.urllib3.connection.VerifiedHTTPSConnection object at 0x0000012DE7C63F98>, 'Connection to api.telegram.org timed out. (connect timeout=5.0)'))
2019-11-02 12:30:40,917 - WARNING - Retrying (Retry(total=2, connect=None, read=None, redirect=None)) after connection broken by 'ConnectTimeoutError(<telegram.vendor.ptb_urllib3.urllib3.connection.VerifiedHTTPSConnection object at 0x0000012DE7C630B8>, 'Connection to api.telegram.org timed out. (connect timeout=5.0)')': /bot822102958:AAHsgSxtLNp1FHMFXih30Rkpkx4DHFsvsFU/getUpdates
2019-11-02 12:30:45,919 - WARNING - Retrying (Retry(total=1, connect=None, read=None, redirect=None)) after connection broken by 'ConnectTimeoutError(<telegram.vendor.ptb_urllib3.urllib3.connection.VerifiedHTTPSConnection object at 0x0000012DE7C63BE0>, 'Connection to api.telegram.org timed out. (connect timeout=5.0)')': /bot822102958:AAHsgSxtLNp1FHMFXih30Rkpkx4DHFsvsFU/getUpdates
2019-11-02 12:30:50,921 - WARNING - Retrying (Retry(total=0, connect=None, read=None, redirect=None)) after connection broken by 'ConnectTimeoutError(<telegram.vendor.ptb_urllib3.urllib3.connection.VerifiedHTTPSConnection object at 0x0000012DE7C78B38>, 'Connection to api.telegram.org timed out. (connect timeout=5.0)')': /bot822102958:AAHsgSxtLNp1FHMFXih30Rkpkx4DHFsvsFU/getUpdates
2019-11-02 12:30:55,922 - ERROR - Error while getting Updates: urllib3 HTTPError HTTPSConnectionPool(host='api.telegram.org', port=443): Max retries exceeded with url: /bot822102958:AAHsgSxtLNp1FHMFXih30Rkpkx4DHFsvsFU/getUpdates (Caused by ConnectTimeoutError(<telegram.vendor.ptb_urllib3.urllib3.connection.VerifiedHTTPSConnection object at 0x0000012DE7C78198>, 'Connection to api.telegram.org timed out. (connect timeout=5.0)'))
2019-11-02 12:30:55,923 - ERROR - No error handlers are registered, logging exception.
Traceback (most recent call last):
  File "c:\projects\next_bot\env\lib\site-packages\telegram\vendor\ptb_urllib3\urllib3\connection.py", line 141, in _new_conn
    (self.host, self.port), self.timeout, **extra_kw)
  File "c:\projects\next_bot\env\lib\site-packages\telegram\vendor\ptb_urllib3\urllib3\util\connection.py", line 83, in create_connection
    raise err
  File "c:\projects\next_bot\env\lib\site-packages\telegram\vendor\ptb_urllib3\urllib3\util\connection.py", line 73, in create_connection
    sock.connect(sa)
socket.timeout: timed out

During handling of the above exception, another exception occurred:

Traceback (most recent call last):
  File "c:\projects\next_bot\env\lib\site-packages\telegram\vendor\ptb_urllib3\urllib3\connectionpool.py", line 617, in urlopen
    chunked=chunked)
  File "c:\projects\next_bot\env\lib\site-packages\telegram\vendor\ptb_urllib3\urllib3\connectionpool.py", line 360, in _make_request
    self._validate_conn(conn)
  File "c:\projects\next_bot\env\lib\site-packages\telegram\vendor\ptb_urllib3\urllib3\connectionpool.py", line 857, in _validate_conn
    super(HTTPSConnectionPool, self)._validate_conn(conn)
  File "c:\projects\next_bot\env\lib\site-packages\telegram\vendor\ptb_urllib3\urllib3\connectionpool.py", line 289, in _validate_conn
    conn.connect()
  File "c:\projects\next_bot\env\lib\site-packages\telegram\vendor\ptb_urllib3\urllib3\connection.py", line 284, in connect
    conn = self._new_conn()
  File "c:\projects\next_bot\env\lib\site-packages\telegram\vendor\ptb_urllib3\urllib3\connection.py", line 146, in _new_conn
    (self.host, self.timeout))
telegram.vendor.ptb_urllib3.urllib3.exceptions.ConnectTimeoutError: (<telegram.vendor.ptb_urllib3.urllib3.connection.VerifiedHTTPSConnection object at 0x0000012DE7C78198>, 'Connection to api.telegram.org timed out. (connect timeout=5.0)')

During handling of the above exception, another exception occurred:

Traceback (most recent call last):
  File "c:\projects\next_bot\env\lib\site-packages\telegram\utils\request.py", line 218, in _request_wrapper
    resp = self._con_pool.request(*args, **kwargs)
  File "c:\projects\next_bot\env\lib\site-packages\telegram\vendor\ptb_urllib3\urllib3\request.py", line 70, in request
    **urlopen_kw)
  File "c:\projects\next_bot\env\lib\site-packages\telegram\vendor\ptb_urllib3\urllib3\request.py", line 148, in request_encode_body
    return self.urlopen(method, url, **extra_kw)
  File "c:\projects\next_bot\env\lib\site-packages\telegram\vendor\ptb_urllib3\urllib3\poolmanager.py", line 244, in urlopen
    response = conn.urlopen(method, u.request_uri, **kw)
  File "c:\projects\next_bot\env\lib\site-packages\telegram\vendor\ptb_urllib3\urllib3\connectionpool.py", line 695, in urlopen
    **response_kw)
  File "c:\projects\next_bot\env\lib\site-packages\telegram\vendor\ptb_urllib3\urllib3\connectionpool.py", line 695, in urlopen
    **response_kw)
  File "c:\projects\next_bot\env\lib\site-packages\telegram\vendor\ptb_urllib3\urllib3\connectionpool.py", line 695, in urlopen
    **response_kw)
  File "c:\projects\next_bot\env\lib\site-packages\telegram\vendor\ptb_urllib3\urllib3\connectionpool.py", line 666, in urlopen
    _stacktrace=sys.exc_info()[2])
  File "c:\projects\next_bot\env\lib\site-packages\telegram\vendor\ptb_urllib3\urllib3\util\retry.py", line 376, in increment
    raise MaxRetryError(_pool, url, error or ResponseError(cause))
telegram.vendor.ptb_urllib3.urllib3.exceptions.MaxRetryError: HTTPSConnectionPool(host='api.telegram.org', port=443): Max retries exceeded with url: /bot822102958:AAHsgSxtLNp1FHMFXih30Rkpkx4DHFsvsFU/getUpdates (Caused by ConnectTimeoutError(<telegram.vendor.ptb_urllib3.urllib3.connection.VerifiedHTTPSConnection object at 0x0000012DE7C78198>, 'Connection to api.telegram.org timed out. (connect timeout=5.0)'))

During handling of the above exception, another exception occurred:

Traceback (most recent call last):
  File "c:\projects\next_bot\env\lib\site-packages\telegram\ext\updater.py", line 332, in _network_loop_retry
    if not action_cb():
  File "c:\projects\next_bot\env\lib\site-packages\telegram\ext\updater.py", line 293, in polling_action_cb
    allowed_updates=allowed_updates)
  File "c:\projects\next_bot\env\lib\site-packages\telegram\bot.py", line 66, in decorator
    result = func(self, *args, **kwargs)
  File "c:\projects\next_bot\env\lib\site-packages\telegram\bot.py", line 1983, in get_updates
    result = self._request.post(url, data, timeout=float(read_latency) + float(timeout))
  File "c:\projects\next_bot\env\lib\site-packages\telegram\utils\request.py", line 327, in post
    **urlopen_kwargs)
  File "c:\projects\next_bot\env\lib\site-packages\telegram\utils\request.py", line 224, in _request_wrapper
    raise NetworkError('urllib3 HTTPError {0}'.format(error))
telegram.error.NetworkError: urllib3 HTTPError HTTPSConnectionPool(host='api.telegram.org', port=443): Max retries exceeded with url: /bot822102958:AAHsgSxtLNp1FHMFXih30Rkpkx4DHFsvsFU/getUpdates (Caused by ConnectTimeoutError(<telegram.vendor.ptb_urllib3.urllib3.connection.VerifiedHTTPSConnection object at 0x0000012DE7C78198>, 'Connection to api.telegram.org timed out. (connect timeout=5.0)'))
2019-11-02 12:31:30,925 - WARNING - Retrying (Retry(total=2, connect=None, read=None, redirect=None)) after connection broken by 'ConnectTimeoutError(<telegram.vendor.ptb_urllib3.urllib3.connection.VerifiedHTTPSConnection object at 0x0000012DE7C78E48>, 'Connection to api.telegram.org timed out. (connect timeout=5.0)')': /bot822102958:AAHsgSxtLNp1FHMFXih30Rkpkx4DHFsvsFU/getUpdates
2019-11-02 12:31:35,927 - WARNING - Retrying (Retry(total=1, connect=None, read=None, redirect=None)) after connection broken by 'ConnectTimeoutError(<telegram.vendor.ptb_urllib3.urllib3.connection.VerifiedHTTPSConnection object at 0x0000012DE7C78FD0>, 'Connection to api.telegram.org timed out. (connect timeout=5.0)')': /bot822102958:AAHsgSxtLNp1FHMFXih30Rkpkx4DHFsvsFU/getUpdates
2019-11-02 12:31:40,928 - WARNING - Retrying (Retry(total=0, connect=None, read=None, redirect=None)) after connection broken by 'ConnectTimeoutError(<telegram.vendor.ptb_urllib3.urllib3.connection.VerifiedHTTPSConnection object at 0x0000012DE7C850F0>, 'Connection to api.telegram.org timed out. (connect timeout=5.0)')': /bot822102958:AAHsgSxtLNp1FHMFXih30Rkpkx4DHFsvsFU/getUpdates
2019-11-02 12:31:45,929 - ERROR - Error while getting Updates: urllib3 HTTPError HTTPSConnectionPool(host='api.telegram.org', port=443): Max retries exceeded with url: /bot822102958:AAHsgSxtLNp1FHMFXih30Rkpkx4DHFsvsFU/getUpdates (Caused by ConnectTimeoutError(<telegram.vendor.ptb_urllib3.urllib3.connection.VerifiedHTTPSConnection object at 0x0000012DE7C85208>, 'Connection to api.telegram.org timed out. (connect timeout=5.0)'))
2019-11-02 12:31:45,929 - ERROR - No error handlers are registered, logging exception.
Traceback (most recent call last):
  File "c:\projects\next_bot\env\lib\site-packages\telegram\vendor\ptb_urllib3\urllib3\connection.py", line 141, in _new_conn
    (self.host, self.port), self.timeout, **extra_kw)
  File "c:\projects\next_bot\env\lib\site-packages\telegram\vendor\ptb_urllib3\urllib3\util\connection.py", line 83, in create_connection
    raise err
  File "c:\projects\next_bot\env\lib\site-packages\telegram\vendor\ptb_urllib3\urllib3\util\connection.py", line 73, in create_connection
    sock.connect(sa)
socket.timeout: timed out

During handling of the above exception, another exception occurred:

Traceback (most recent call last):
  File "c:\projects\next_bot\env\lib\site-packages\telegram\vendor\ptb_urllib3\urllib3\connectionpool.py", line 617, in urlopen
    chunked=chunked)
  File "c:\projects\next_bot\env\lib\site-packages\telegram\vendor\ptb_urllib3\urllib3\connectionpool.py", line 360, in _make_request
    self._validate_conn(conn)
  File "c:\projects\next_bot\env\lib\site-packages\telegram\vendor\ptb_urllib3\urllib3\connectionpool.py", line 857, in _validate_conn
    super(HTTPSConnectionPool, self)._validate_conn(conn)
  File "c:\projects\next_bot\env\lib\site-packages\telegram\vendor\ptb_urllib3\urllib3\connectionpool.py", line 289, in _validate_conn
    conn.connect()
  File "c:\projects\next_bot\env\lib\site-packages\telegram\vendor\ptb_urllib3\urllib3\connection.py", line 284, in connect
    conn = self._new_conn()
  File "c:\projects\next_bot\env\lib\site-packages\telegram\vendor\ptb_urllib3\urllib3\connection.py", line 146, in _new_conn
    (self.host, self.timeout))
telegram.vendor.ptb_urllib3.urllib3.exceptions.ConnectTimeoutError: (<telegram.vendor.ptb_urllib3.urllib3.connection.VerifiedHTTPSConnection object at 0x0000012DE7C85208>, 'Connection to api.telegram.org timed out. (connect timeout=5.0)')

During handling of the above exception, another exception occurred:

Traceback (most recent call last):
  File "c:\projects\next_bot\env\lib\site-packages\telegram\utils\request.py", line 218, in _request_wrapper
    resp = self._con_pool.request(*args, **kwargs)
  File "c:\projects\next_bot\env\lib\site-packages\telegram\vendor\ptb_urllib3\urllib3\request.py", line 70, in request
    **urlopen_kw)
  File "c:\projects\next_bot\env\lib\site-packages\telegram\vendor\ptb_urllib3\urllib3\request.py", line 148, in request_encode_body
    return self.urlopen(method, url, **extra_kw)
  File "c:\projects\next_bot\env\lib\site-packages\telegram\vendor\ptb_urllib3\urllib3\poolmanager.py", line 244, in urlopen
    response = conn.urlopen(method, u.request_uri, **kw)
  File "c:\projects\next_bot\env\lib\site-packages\telegram\vendor\ptb_urllib3\urllib3\connectionpool.py", line 695, in urlopen
    **response_kw)
  File "c:\projects\next_bot\env\lib\site-packages\telegram\vendor\ptb_urllib3\urllib3\connectionpool.py", line 695, in urlopen
    **response_kw)
  File "c:\projects\next_bot\env\lib\site-packages\telegram\vendor\ptb_urllib3\urllib3\connectionpool.py", line 695, in urlopen
    **response_kw)
  File "c:\projects\next_bot\env\lib\site-packages\telegram\vendor\ptb_urllib3\urllib3\connectionpool.py", line 666, in urlopen
    _stacktrace=sys.exc_info()[2])
  File "c:\projects\next_bot\env\lib\site-packages\telegram\vendor\ptb_urllib3\urllib3\util\retry.py", line 376, in increment
    raise MaxRetryError(_pool, url, error or ResponseError(cause))
telegram.vendor.ptb_urllib3.urllib3.exceptions.MaxRetryError: HTTPSConnectionPool(host='api.telegram.org', port=443): Max retries exceeded with url: /bot822102958:AAHsgSxtLNp1FHMFXih30Rkpkx4DHFsvsFU/getUpdates (Caused by ConnectTimeoutError(<telegram.vendor.ptb_urllib3.urllib3.connection.VerifiedHTTPSConnection object at 0x0000012DE7C85208>, 'Connection to api.telegram.org timed out. (connect timeout=5.0)'))

During handling of the above exception, another exception occurred:

Traceback (most recent call last):
  File "c:\projects\next_bot\env\lib\site-packages\telegram\ext\updater.py", line 332, in _network_loop_retry
    if not action_cb():
  File "c:\projects\next_bot\env\lib\site-packages\telegram\ext\updater.py", line 293, in polling_action_cb
    allowed_updates=allowed_updates)
  File "c:\projects\next_bot\env\lib\site-packages\telegram\bot.py", line 66, in decorator
    result = func(self, *args, **kwargs)
  File "c:\projects\next_bot\env\lib\site-packages\telegram\bot.py", line 1983, in get_updates
    result = self._request.post(url, data, timeout=float(read_latency) + float(timeout))
  File "c:\projects\next_bot\env\lib\site-packages\telegram\utils\request.py", line 327, in post
    **urlopen_kwargs)
  File "c:\projects\next_bot\env\lib\site-packages\telegram\utils\request.py", line 224, in _request_wrapper
    raise NetworkError('urllib3 HTTPError {0}'.format(error))
telegram.error.NetworkError: urllib3 HTTPError HTTPSConnectionPool(host='api.telegram.org', port=443): Max retries exceeded with url: /bot822102958:AAHsgSxtLNp1FHMFXih30Rkpkx4DHFsvsFU/getUpdates (Caused by ConnectTimeoutError(<telegram.vendor.ptb_urllib3.urllib3.connection.VerifiedHTTPSConnection object at 0x0000012DE7C85208>, 'Connection to api.telegram.org timed out. (connect timeout=5.0)'))
2019-11-02 12:32:20,931 - WARNING - Retrying (Retry(total=2, connect=None, read=None, redirect=None)) after connection broken by 'ConnectTimeoutError(<telegram.vendor.ptb_urllib3.urllib3.connection.VerifiedHTTPSConnection object at 0x0000012DE7C85438>, 'Connection to api.telegram.org timed out. (connect timeout=5.0)')': /bot822102958:AAHsgSxtLNp1FHMFXih30Rkpkx4DHFsvsFU/getUpdates
2019-11-02 12:32:25,933 - WARNING - Retrying (Retry(total=1, connect=None, read=None, redirect=None)) after connection broken by 'ConnectTimeoutError(<telegram.vendor.ptb_urllib3.urllib3.connection.VerifiedHTTPSConnection object at 0x0000012DE7C855C0>, 'Connection to api.telegram.org timed out. (connect timeout=5.0)')': /bot822102958:AAHsgSxtLNp1FHMFXih30Rkpkx4DHFsvsFU/getUpdates
2019-11-02 12:32:30,946 - WARNING - Retrying (Retry(total=0, connect=None, read=None, redirect=None)) after connection broken by 'ConnectTimeoutError(<telegram.vendor.ptb_urllib3.urllib3.connection.VerifiedHTTPSConnection object at 0x0000012DE7C856A0>, 'Connection to api.telegram.org timed out. (connect timeout=5.0)')': /bot822102958:AAHsgSxtLNp1FHMFXih30Rkpkx4DHFsvsFU/getUpdates
2019-11-02 12:32:35,947 - ERROR - Error while getting Updates: urllib3 HTTPError HTTPSConnectionPool(host='api.telegram.org', port=443): Max retries exceeded with url: /bot822102958:AAHsgSxtLNp1FHMFXih30Rkpkx4DHFsvsFU/getUpdates (Caused by ConnectTimeoutError(<telegram.vendor.ptb_urllib3.urllib3.connection.VerifiedHTTPSConnection object at 0x0000012DE7C857B8>, 'Connection to api.telegram.org timed out. (connect timeout=5.0)'))
2019-11-02 12:32:35,947 - ERROR - No error handlers are registered, logging exception.
Traceback (most recent call last):
  File "c:\projects\next_bot\env\lib\site-packages\telegram\vendor\ptb_urllib3\urllib3\connection.py", line 141, in _new_conn
    (self.host, self.port), self.timeout, **extra_kw)
  File "c:\projects\next_bot\env\lib\site-packages\telegram\vendor\ptb_urllib3\urllib3\util\connection.py", line 83, in create_connection
    raise err
  File "c:\projects\next_bot\env\lib\site-packages\telegram\vendor\ptb_urllib3\urllib3\util\connection.py", line 73, in create_connection
    sock.connect(sa)
socket.timeout: timed out

During handling of the above exception, another exception occurred:

Traceback (most recent call last):
  File "c:\projects\next_bot\env\lib\site-packages\telegram\vendor\ptb_urllib3\urllib3\connectionpool.py", line 617, in urlopen
    chunked=chunked)
  File "c:\projects\next_bot\env\lib\site-packages\telegram\vendor\ptb_urllib3\urllib3\connectionpool.py", line 360, in _make_request
    self._validate_conn(conn)
  File "c:\projects\next_bot\env\lib\site-packages\telegram\vendor\ptb_urllib3\urllib3\connectionpool.py", line 857, in _validate_conn
    super(HTTPSConnectionPool, self)._validate_conn(conn)
  File "c:\projects\next_bot\env\lib\site-packages\telegram\vendor\ptb_urllib3\urllib3\connectionpool.py", line 289, in _validate_conn
    conn.connect()
  File "c:\projects\next_bot\env\lib\site-packages\telegram\vendor\ptb_urllib3\urllib3\connection.py", line 284, in connect
    conn = self._new_conn()
  File "c:\projects\next_bot\env\lib\site-packages\telegram\vendor\ptb_urllib3\urllib3\connection.py", line 146, in _new_conn
    (self.host, self.timeout))
telegram.vendor.ptb_urllib3.urllib3.exceptions.ConnectTimeoutError: (<telegram.vendor.ptb_urllib3.urllib3.connection.VerifiedHTTPSConnection object at 0x0000012DE7C857B8>, 'Connection to api.telegram.org timed out. (connect timeout=5.0)')

During handling of the above exception, another exception occurred:

Traceback (most recent call last):
  File "c:\projects\next_bot\env\lib\site-packages\telegram\utils\request.py", line 218, in _request_wrapper
    resp = self._con_pool.request(*args, **kwargs)
  File "c:\projects\next_bot\env\lib\site-packages\telegram\vendor\ptb_urllib3\urllib3\request.py", line 70, in request
    **urlopen_kw)
  File "c:\projects\next_bot\env\lib\site-packages\telegram\vendor\ptb_urllib3\urllib3\request.py", line 148, in request_encode_body
    return self.urlopen(method, url, **extra_kw)
  File "c:\projects\next_bot\env\lib\site-packages\telegram\vendor\ptb_urllib3\urllib3\poolmanager.py", line 244, in urlopen
    response = conn.urlopen(method, u.request_uri, **kw)
  File "c:\projects\next_bot\env\lib\site-packages\telegram\vendor\ptb_urllib3\urllib3\connectionpool.py", line 695, in urlopen
    **response_kw)
  File "c:\projects\next_bot\env\lib\site-packages\telegram\vendor\ptb_urllib3\urllib3\connectionpool.py", line 695, in urlopen
    **response_kw)
  File "c:\projects\next_bot\env\lib\site-packages\telegram\vendor\ptb_urllib3\urllib3\connectionpool.py", line 695, in urlopen
    **response_kw)
  File "c:\projects\next_bot\env\lib\site-packages\telegram\vendor\ptb_urllib3\urllib3\connectionpool.py", line 666, in urlopen
    _stacktrace=sys.exc_info()[2])
  File "c:\projects\next_bot\env\lib\site-packages\telegram\vendor\ptb_urllib3\urllib3\util\retry.py", line 376, in increment
    raise MaxRetryError(_pool, url, error or ResponseError(cause))
telegram.vendor.ptb_urllib3.urllib3.exceptions.MaxRetryError: HTTPSConnectionPool(host='api.telegram.org', port=443): Max retries exceeded with url: /bot822102958:AAHsgSxtLNp1FHMFXih30Rkpkx4DHFsvsFU/getUpdates (Caused by ConnectTimeoutError(<telegram.vendor.ptb_urllib3.urllib3.connection.VerifiedHTTPSConnection object at 0x0000012DE7C857B8>, 'Connection to api.telegram.org timed out. (connect timeout=5.0)'))

During handling of the above exception, another exception occurred:

Traceback (most recent call last):
  File "c:\projects\next_bot\env\lib\site-packages\telegram\ext\updater.py", line 332, in _network_loop_retry
    if not action_cb():
  File "c:\projects\next_bot\env\lib\site-packages\telegram\ext\updater.py", line 293, in polling_action_cb
    allowed_updates=allowed_updates)
  File "c:\projects\next_bot\env\lib\site-packages\telegram\bot.py", line 66, in decorator
    result = func(self, *args, **kwargs)
  File "c:\projects\next_bot\env\lib\site-packages\telegram\bot.py", line 1983, in get_updates
    result = self._request.post(url, data, timeout=float(read_latency) + float(timeout))
  File "c:\projects\next_bot\env\lib\site-packages\telegram\utils\request.py", line 327, in post
    **urlopen_kwargs)
  File "c:\projects\next_bot\env\lib\site-packages\telegram\utils\request.py", line 224, in _request_wrapper
    raise NetworkError('urllib3 HTTPError {0}'.format(error))
telegram.error.NetworkError: urllib3 HTTPError HTTPSConnectionPool(host='api.telegram.org', port=443): Max retries exceeded with url: /bot822102958:AAHsgSxtLNp1FHMFXih30Rkpkx4DHFsvsFU/getUpdates (Caused by ConnectTimeoutError(<telegram.vendor.ptb_urllib3.urllib3.connection.VerifiedHTTPSConnection object at 0x0000012DE7C857B8>, 'Connection to api.telegram.org timed out. (connect timeout=5.0)'))
2019-11-02 12:33:10,949 - WARNING - Retrying (Retry(total=2, connect=None, read=None, redirect=None)) after connection broken by 'ConnectTimeoutError(<telegram.vendor.ptb_urllib3.urllib3.connection.VerifiedHTTPSConnection object at 0x0000012DE7C78C18>, 'Connection to api.telegram.org timed out. (connect timeout=5.0)')': /bot822102958:AAHsgSxtLNp1FHMFXih30Rkpkx4DHFsvsFU/getUpdates
2019-11-02 12:33:15,951 - WARNING - Retrying (Retry(total=1, connect=None, read=None, redirect=None)) after connection broken by 'ConnectTimeoutError(<telegram.vendor.ptb_urllib3.urllib3.connection.VerifiedHTTPSConnection object at 0x0000012DE7C630F0>, 'Connection to api.telegram.org timed out. (connect timeout=5.0)')': /bot822102958:AAHsgSxtLNp1FHMFXih30Rkpkx4DHFsvsFU/getUpdates
2019-11-02 12:33:20,952 - WARNING - Retrying (Retry(total=0, connect=None, read=None, redirect=None)) after connection broken by 'ConnectTimeoutError(<telegram.vendor.ptb_urllib3.urllib3.connection.VerifiedHTTPSConnection object at 0x0000012DE7C63CC0>, 'Connection to api.telegram.org timed out. (connect timeout=5.0)')': /bot822102958:AAHsgSxtLNp1FHMFXih30Rkpkx4DHFsvsFU/getUpdates
2019-11-02 12:33:25,953 - ERROR - Error while getting Updates: urllib3 HTTPError HTTPSConnectionPool(host='api.telegram.org', port=443): Max retries exceeded with url: /bot822102958:AAHsgSxtLNp1FHMFXih30Rkpkx4DHFsvsFU/getUpdates (Caused by ConnectTimeoutError(<telegram.vendor.ptb_urllib3.urllib3.connection.VerifiedHTTPSConnection object at 0x0000012DE7C63FD0>, 'Connection to api.telegram.org timed out. (connect timeout=5.0)'))
2019-11-02 12:33:25,953 - ERROR - No error handlers are registered, logging exception.
Traceback (most recent call last):
  File "c:\projects\next_bot\env\lib\site-packages\telegram\vendor\ptb_urllib3\urllib3\connection.py", line 141, in _new_conn
    (self.host, self.port), self.timeout, **extra_kw)
  File "c:\projects\next_bot\env\lib\site-packages\telegram\vendor\ptb_urllib3\urllib3\util\connection.py", line 83, in create_connection
    raise err
  File "c:\projects\next_bot\env\lib\site-packages\telegram\vendor\ptb_urllib3\urllib3\util\connection.py", line 73, in create_connection
    sock.connect(sa)
socket.timeout: timed out

During handling of the above exception, another exception occurred:

Traceback (most recent call last):
  File "c:\projects\next_bot\env\lib\site-packages\telegram\vendor\ptb_urllib3\urllib3\connectionpool.py", line 617, in urlopen
    chunked=chunked)
  File "c:\projects\next_bot\env\lib\site-packages\telegram\vendor\ptb_urllib3\urllib3\connectionpool.py", line 360, in _make_request
    self._validate_conn(conn)
  File "c:\projects\next_bot\env\lib\site-packages\telegram\vendor\ptb_urllib3\urllib3\connectionpool.py", line 857, in _validate_conn
    super(HTTPSConnectionPool, self)._validate_conn(conn)
  File "c:\projects\next_bot\env\lib\site-packages\telegram\vendor\ptb_urllib3\urllib3\connectionpool.py", line 289, in _validate_conn
    conn.connect()
  File "c:\projects\next_bot\env\lib\site-packages\telegram\vendor\ptb_urllib3\urllib3\connection.py", line 284, in connect
    conn = self._new_conn()
  File "c:\projects\next_bot\env\lib\site-packages\telegram\vendor\ptb_urllib3\urllib3\connection.py", line 146, in _new_conn
    (self.host, self.timeout))
telegram.vendor.ptb_urllib3.urllib3.exceptions.ConnectTimeoutError: (<telegram.vendor.ptb_urllib3.urllib3.connection.VerifiedHTTPSConnection object at 0x0000012DE7C63FD0>, 'Connection to api.telegram.org timed out. (connect timeout=5.0)')

During handling of the above exception, another exception occurred:

Traceback (most recent call last):
  File "c:\projects\next_bot\env\lib\site-packages\telegram\utils\request.py", line 218, in _request_wrapper
    resp = self._con_pool.request(*args, **kwargs)
  File "c:\projects\next_bot\env\lib\site-packages\telegram\vendor\ptb_urllib3\urllib3\request.py", line 70, in request
    **urlopen_kw)
  File "c:\projects\next_bot\env\lib\site-packages\telegram\vendor\ptb_urllib3\urllib3\request.py", line 148, in request_encode_body
    return self.urlopen(method, url, **extra_kw)
  File "c:\projects\next_bot\env\lib\site-packages\telegram\vendor\ptb_urllib3\urllib3\poolmanager.py", line 244, in urlopen
    response = conn.urlopen(method, u.request_uri, **kw)
  File "c:\projects\next_bot\env\lib\site-packages\telegram\vendor\ptb_urllib3\urllib3\connectionpool.py", line 695, in urlopen
    **response_kw)
  File "c:\projects\next_bot\env\lib\site-packages\telegram\vendor\ptb_urllib3\urllib3\connectionpool.py", line 695, in urlopen
    **response_kw)
  File "c:\projects\next_bot\env\lib\site-packages\telegram\vendor\ptb_urllib3\urllib3\connectionpool.py", line 695, in urlopen
    **response_kw)
  File "c:\projects\next_bot\env\lib\site-packages\telegram\vendor\ptb_urllib3\urllib3\connectionpool.py", line 666, in urlopen
    _stacktrace=sys.exc_info()[2])
  File "c:\projects\next_bot\env\lib\site-packages\telegram\vendor\ptb_urllib3\urllib3\util\retry.py", line 376, in increment
    raise MaxRetryError(_pool, url, error or ResponseError(cause))
telegram.vendor.ptb_urllib3.urllib3.exceptions.MaxRetryError: HTTPSConnectionPool(host='api.telegram.org', port=443): Max retries exceeded with url: /bot822102958:AAHsgSxtLNp1FHMFXih30Rkpkx4DHFsvsFU/getUpdates (Caused by ConnectTimeoutError(<telegram.vendor.ptb_urllib3.urllib3.connection.VerifiedHTTPSConnection object at 0x0000012DE7C63FD0>, 'Connection to api.telegram.org timed out. (connect timeout=5.0)'))

During handling of the above exception, another exception occurred:

Traceback (most recent call last):
  File "c:\projects\next_bot\env\lib\site-packages\telegram\ext\updater.py", line 332, in _network_loop_retry
    if not action_cb():
  File "c:\projects\next_bot\env\lib\site-packages\telegram\ext\updater.py", line 293, in polling_action_cb
    allowed_updates=allowed_updates)
  File "c:\projects\next_bot\env\lib\site-packages\telegram\bot.py", line 66, in decorator
    result = func(self, *args, **kwargs)
  File "c:\projects\next_bot\env\lib\site-packages\telegram\bot.py", line 1983, in get_updates
    result = self._request.post(url, data, timeout=float(read_latency) + float(timeout))
  File "c:\projects\next_bot\env\lib\site-packages\telegram\utils\request.py", line 327, in post
    **urlopen_kwargs)
  File "c:\projects\next_bot\env\lib\site-packages\telegram\utils\request.py", line 224, in _request_wrapper
    raise NetworkError('urllib3 HTTPError {0}'.format(error))
telegram.error.NetworkError: urllib3 HTTPError HTTPSConnectionPool(host='api.telegram.org', port=443): Max retries exceeded with url: /bot822102958:AAHsgSxtLNp1FHMFXih30Rkpkx4DHFsvsFU/getUpdates (Caused by ConnectTimeoutError(<telegram.vendor.ptb_urllib3.urllib3.connection.VerifiedHTTPSConnection object at 0x0000012DE7C63FD0>, 'Connection to api.telegram.org timed out. (connect timeout=5.0)'))
2019-11-02 12:33:32,805 - INFO - Бот стартанул
2019-11-02 12:33:32,806 - WARNING - Connection pool of Request object is smaller than optimal value (8)
2019-11-02 12:33:37,827 - WARNING - Retrying (Retry(total=2, connect=None, read=None, redirect=None)) after connection broken by 'ConnectTimeoutError(<telegram.vendor.ptb_urllib3.urllib3.connection.VerifiedHTTPSConnection object at 0x0000017991C813C8>, 'Connection to api.telegram.org timed out. (connect timeout=5.0)')': /bot822102958:AAHsgSxtLNp1FHMFXih30Rkpkx4DHFsvsFU/getMe
2019-11-02 12:33:42,828 - WARNING - Retrying (Retry(total=1, connect=None, read=None, redirect=None)) after connection broken by 'ConnectTimeoutError(<telegram.vendor.ptb_urllib3.urllib3.connection.VerifiedHTTPSConnection object at 0x0000017991C814E0>, 'Connection to api.telegram.org timed out. (connect timeout=5.0)')': /bot822102958:AAHsgSxtLNp1FHMFXih30Rkpkx4DHFsvsFU/getMe
2019-11-02 12:33:47,830 - WARNING - Retrying (Retry(total=0, connect=None, read=None, redirect=None)) after connection broken by 'ConnectTimeoutError(<telegram.vendor.ptb_urllib3.urllib3.connection.VerifiedHTTPSConnection object at 0x0000017991C815C0>, 'Connection to api.telegram.org timed out. (connect timeout=5.0)')': /bot822102958:AAHsgSxtLNp1FHMFXih30Rkpkx4DHFsvsFU/getMe
2019-11-02 12:35:43,773 - INFO - Бот стартанул
2019-11-02 12:35:43,773 - WARNING - Connection pool of Request object is smaller than optimal value (8)
2019-11-02 12:35:52,825 - WARNING - Connection pool is full, discarding connection: api.telegram.org
2019-11-02 12:35:53,141 - INFO - Запущена  signup_start
2019-11-02 12:36:02,897 - WARNING - Connection pool is full, discarding connection: api.telegram.org
2019-11-02 12:36:07,848 - INFO - Запущена  signup_get_name_and_surname
2019-11-02 12:36:07,848 - INFO - Запущена  signup_get_name_and_surname  юзер ввел  2 строки. Имя и фамилия сохранены
2019-11-02 12:36:17,912 - WARNING - Connection pool is full, discarding connection: api.telegram.org
2019-11-02 12:37:03,421 - WARNING - Connection pool is full, discarding connection: api.telegram.org
2019-11-02 12:39:28,539 - WARNING - Connection pool is full, discarding connection: api.telegram.org
2019-11-02 12:39:28,877 - INFO - Запущена  signup_start
2019-11-02 12:39:32,926 - WARNING - Connection pool is full, discarding connection: api.telegram.org
2019-11-02 12:39:32,928 - INFO - Запущена  signup_get_name_and_surname
2019-11-02 12:39:32,928 - INFO - Запущена  signup_get_name_and_surname  юзер ввел  2 строки. Имя и фамилия сохранены
2019-11-02 12:39:40,761 - WARNING - Connection pool is full, discarding connection: api.telegram.org
2019-11-02 12:43:02,508 - WARNING - Connection pool is full, discarding connection: api.telegram.org
2019-11-02 12:43:34,402 - INFO - Бот стартанул
2019-11-02 12:43:34,402 - WARNING - Connection pool of Request object is smaller than optimal value (8)
2019-11-02 12:43:47,877 - WARNING - Connection pool is full, discarding connection: api.telegram.org
2019-11-02 12:43:48,193 - INFO - Запущена  signup_start
2019-11-02 12:43:55,245 - WARNING - Connection pool is full, discarding connection: api.telegram.org
2019-11-02 12:43:55,247 - INFO - Запущена  signup_get_name_and_surname
2019-11-02 12:43:55,247 - INFO - Запущена  signup_get_name_and_surname  юзер ввел  2 строки. Имя и фамилия сохранены
2019-11-02 12:44:05,377 - WARNING - Connection pool is full, discarding connection: api.telegram.org
2019-11-02 12:47:04,513 - WARNING - Connection pool is full, discarding connection: api.telegram.org
2019-11-02 13:03:17,284 - INFO - Бот стартанул
2019-11-02 13:03:17,284 - WARNING - Connection pool of Request object is smaller than optimal value (8)
2019-11-02 13:03:39,642 - WARNING - Connection pool is full, discarding connection: api.telegram.org
2019-11-02 13:03:39,949 - INFO - Запущена  signup_start
2019-11-02 13:03:44,667 - WARNING - Connection pool is full, discarding connection: api.telegram.org
2019-11-02 13:03:44,669 - INFO - Запущена  signup_get_name_and_surname
2019-11-02 13:03:44,975 - INFO -  vvod 1 Запущена  signup_get_name_and_surname  юзер ввел не 2 строки
2019-11-02 13:03:50,459 - WARNING - Connection pool is full, discarding connection: api.telegram.org
2019-11-02 13:03:50,461 - INFO - Запущена  signup_get_name_and_surname
2019-11-02 13:03:50,461 - INFO - Запущена  signup_get_name_and_surname  юзер ввел  2 строки. Имя и фамилия сохранены
2019-11-02 13:03:57,211 - WARNING - Connection pool is full, discarding connection: api.telegram.org
2019-11-02 13:42:33,268 - INFO - Бот стартанул
2019-11-02 13:42:33,269 - WARNING - Connection pool of Request object is smaller than optimal value (8)
2019-11-02 13:42:41,281 - WARNING - Connection pool is full, discarding connection: api.telegram.org
2019-11-02 13:42:41,606 - INFO - Запущена  signup_start
2019-11-02 13:42:51,125 - WARNING - Connection pool is full, discarding connection: api.telegram.org
2019-11-02 13:42:51,127 - INFO - Запущена  signup_get_name_and_surname
2019-11-02 13:42:51,127 - INFO - Запущена  signup_get_name_and_surname  юзер ввел  2 строки. Имя и фамилия сохранены
2019-11-02 13:43:01,196 - WARNING - Connection pool is full, discarding connection: api.telegram.org
2019-11-02 13:56:44,346 - WARNING - Connection pool is full, discarding connection: api.telegram.org
2019-11-02 13:57:09,581 - INFO - Запущена login_start 
2019-11-02 13:57:19,656 - WARNING - Connection pool is full, discarding connection: api.telegram.org
2019-11-02 13:58:45,356 - ERROR - Error while getting Updates: urllib3 HTTPError ('Connection aborted.', ConnectionResetError(10054, 'Удаленный хост принудительно разорвал существующее подключение', None, 10054, None))
2019-11-02 13:58:45,356 - ERROR - No error handlers are registered, logging exception.
Traceback (most recent call last):
  File "c:\projects\next_bot\env\lib\site-packages\telegram\vendor\ptb_urllib3\urllib3\connectionpool.py", line 617, in urlopen
    chunked=chunked)
  File "c:\projects\next_bot\env\lib\site-packages\telegram\vendor\ptb_urllib3\urllib3\connectionpool.py", line 402, in _make_request
    six.raise_from(e, None)
  File "<string>", line 2, in raise_from
  File "c:\projects\next_bot\env\lib\site-packages\telegram\vendor\ptb_urllib3\urllib3\connectionpool.py", line 398, in _make_request
    httplib_response = conn.getresponse()
  File "C:\Program Files\Python\Python373\lib\http\client.py", line 1321, in getresponse
    response.begin()
  File "C:\Program Files\Python\Python373\lib\http\client.py", line 296, in begin
    version, status, reason = self._read_status()
  File "C:\Program Files\Python\Python373\lib\http\client.py", line 257, in _read_status
    line = str(self.fp.readline(_MAXLINE + 1), "iso-8859-1")
  File "C:\Program Files\Python\Python373\lib\socket.py", line 589, in readinto
    return self._sock.recv_into(b)
  File "C:\Program Files\Python\Python373\lib\ssl.py", line 1052, in recv_into
    return self.read(nbytes, buffer)
  File "C:\Program Files\Python\Python373\lib\ssl.py", line 911, in read
    return self._sslobj.read(len, buffer)
ConnectionResetError: [WinError 10054] Удаленный хост принудительно разорвал существующее подключение

During handling of the above exception, another exception occurred:

Traceback (most recent call last):
  File "c:\projects\next_bot\env\lib\site-packages\telegram\utils\request.py", line 218, in _request_wrapper
    resp = self._con_pool.request(*args, **kwargs)
  File "c:\projects\next_bot\env\lib\site-packages\telegram\vendor\ptb_urllib3\urllib3\request.py", line 70, in request
    **urlopen_kw)
  File "c:\projects\next_bot\env\lib\site-packages\telegram\vendor\ptb_urllib3\urllib3\request.py", line 148, in request_encode_body
    return self.urlopen(method, url, **extra_kw)
  File "c:\projects\next_bot\env\lib\site-packages\telegram\vendor\ptb_urllib3\urllib3\poolmanager.py", line 244, in urlopen
    response = conn.urlopen(method, u.request_uri, **kw)
  File "c:\projects\next_bot\env\lib\site-packages\telegram\vendor\ptb_urllib3\urllib3\connectionpool.py", line 666, in urlopen
    _stacktrace=sys.exc_info()[2])
  File "c:\projects\next_bot\env\lib\site-packages\telegram\vendor\ptb_urllib3\urllib3\util\retry.py", line 347, in increment
    raise six.reraise(type(error), error, _stacktrace)
  File "c:\projects\next_bot\env\lib\site-packages\telegram\vendor\ptb_urllib3\urllib3\packages\six.py", line 685, in reraise
    raise value.with_traceback(tb)
  File "c:\projects\next_bot\env\lib\site-packages\telegram\vendor\ptb_urllib3\urllib3\connectionpool.py", line 617, in urlopen
    chunked=chunked)
  File "c:\projects\next_bot\env\lib\site-packages\telegram\vendor\ptb_urllib3\urllib3\connectionpool.py", line 402, in _make_request
    six.raise_from(e, None)
  File "<string>", line 2, in raise_from
  File "c:\projects\next_bot\env\lib\site-packages\telegram\vendor\ptb_urllib3\urllib3\connectionpool.py", line 398, in _make_request
    httplib_response = conn.getresponse()
  File "C:\Program Files\Python\Python373\lib\http\client.py", line 1321, in getresponse
    response.begin()
  File "C:\Program Files\Python\Python373\lib\http\client.py", line 296, in begin
    version, status, reason = self._read_status()
  File "C:\Program Files\Python\Python373\lib\http\client.py", line 257, in _read_status
    line = str(self.fp.readline(_MAXLINE + 1), "iso-8859-1")
  File "C:\Program Files\Python\Python373\lib\socket.py", line 589, in readinto
    return self._sock.recv_into(b)
  File "C:\Program Files\Python\Python373\lib\ssl.py", line 1052, in recv_into
    return self.read(nbytes, buffer)
  File "C:\Program Files\Python\Python373\lib\ssl.py", line 911, in read
    return self._sslobj.read(len, buffer)
telegram.vendor.ptb_urllib3.urllib3.exceptions.ProtocolError: ('Connection aborted.', ConnectionResetError(10054, 'Удаленный хост принудительно разорвал существующее подключение', None, 10054, None))

During handling of the above exception, another exception occurred:

Traceback (most recent call last):
  File "c:\projects\next_bot\env\lib\site-packages\telegram\ext\updater.py", line 332, in _network_loop_retry
    if not action_cb():
  File "c:\projects\next_bot\env\lib\site-packages\telegram\ext\updater.py", line 293, in polling_action_cb
    allowed_updates=allowed_updates)
  File "c:\projects\next_bot\env\lib\site-packages\telegram\bot.py", line 66, in decorator
    result = func(self, *args, **kwargs)
  File "c:\projects\next_bot\env\lib\site-packages\telegram\bot.py", line 1983, in get_updates
    result = self._request.post(url, data, timeout=float(read_latency) + float(timeout))
  File "c:\projects\next_bot\env\lib\site-packages\telegram\utils\request.py", line 327, in post
    **urlopen_kwargs)
  File "c:\projects\next_bot\env\lib\site-packages\telegram\utils\request.py", line 224, in _request_wrapper
    raise NetworkError('urllib3 HTTPError {0}'.format(error))
telegram.error.NetworkError: urllib3 HTTPError ('Connection aborted.', ConnectionResetError(10054, 'Удаленный хост принудительно разорвал существующее подключение', None, 10054, None))
2019-11-02 13:58:51,375 - WARNING - Retrying (Retry(total=2, connect=None, read=None, redirect=None)) after connection broken by 'ConnectTimeoutError(<telegram.vendor.ptb_urllib3.urllib3.connection.VerifiedHTTPSConnection object at 0x0000025E4B241C50>, 'Connection to api.telegram.org timed out. (connect timeout=5.0)')': /bot822102958:AAHsgSxtLNp1FHMFXih30Rkpkx4DHFsvsFU/getUpdates
